Workbook
Name central_anc_access_rate: Assumptions!$D$5
Name central_anc_access_rate_growth: Assumptions!$E$5
Name central_anc_access_rate_positive: Assumptions!$F$5
Name central_anc_access_rate_positive_growth: Assumptions!$G$5
Name central_launch_budget: Assumptions!$D$117
Name central_launch_budget_growth: Assumptions!$E$117
Name central_launch_budget_positive: Assumptions!$F$117
Name central_launch_budget_positive_growth: Assumptions!$G$117
Name central_private_acceptance_rate: Assumptions!$D$46
Name central_private_acceptance_rate_growth: Assumptions!$E$46
Name central_private_acceptance_rate_positive: Assumptions!$F$46
Name central_private_acceptance_rate_positive_growth: Assumptions!$G$46
Name central_private_coverage_additions: Assumptions!$D$48
Name central_private_coverage_additions_growth: Assumptions!$E$48
Name central_private_coverage_additions_positive: Assumptions!$F$48
Name central_private_coverage_additions_positive_growth: Assumptions!$G$48
Name central_private_coverage_churn: Assumptions!$D$49
Name central_private_coverage_churn_growth: Assumptions!$E$49
Name central_private_coverage_churn_positive: Assumptions!$F$49
Name central_private_coverage_churn_positive_growth: Assumptions!$G$49
Name central_private_distribution_cost_per_dose: Assumptions!$D$80
Name central_private_distribution_cost_per_dose_growth: Assumptions!$E$80
Name central_private_distribution_cost_per_dose_positive: Assumptions!$F$80
Name central_private_distribution_cost_per_dose_positive_growth: Assumptions!$G$80
Name central_private_eligibility_rate: Assumptions!$D$44
Name central_private_eligibility_rate_growth: Assumptions!$E$44
Name central_private_eligibility_rate_positive: Assumptions!$F$44
Name central_private_eligibility_rate_positive_growth: Assumptions!$G$44
Name central_private_net_price_per_dose: Assumptions!$D$50
Name central_private_net_price_per_dose_growth: Assumptions!$E$50
Name central_private_net_price_per_dose_positive: Assumptions!$F$50
Name central_private_net_price_per_dose_positive_growth: Assumptions!$G$50
Name central_private_provider_recommendation_rate: Assumptions!$D$45
Name central_private_provider_recommendation_rate_growth: Assumptions!$E$45
Name central_private_provider_recommendation_rate_positive: Assumptions!$F$45
Name central_private_provider_recommendation_rate_positive_growth: Assumptions!$G$45
Name central_private_stock_availability_rate: Assumptions!$D$47
Name central_private_stock_availability_rate_growth: Assumptions!$E$47
Name central_private_stock_availability_rate_positive: Assumptions!$F$47
Name central_private_stock_availability_rate_positive_growth: Assumptions!$G$47
Name central_private_trade_support_per_dose: Assumptions!$D$92
Name central_private_trade_support_per_dose_growth: Assumptions!$E$92
Name central_private_trade_support_per_dose_positive: Assumptions!$F$92
Name central_private_trade_support_per_dose_positive_growth: Assumptions!$G$92
Name central_private_wastage_rate: Assumptions!$D$88
Name central_private_wastage_rate_growth: Assumptions!$E$88
Name central_private_wastage_rate_positive: Assumptions!$F$88
Name central_private_wastage_rate_positive_growth: Assumptions!$G$88
Name central_public_acceptance_rate: Assumptions!$D$9
Name central_public_acceptance_rate_growth: Assumptions!$E$9
Name central_public_acceptance_rate_positive: Assumptions!$F$9
Name central_public_acceptance_rate_positive_growth: Assumptions!$G$9
Name central_public_coverage_additions: Assumptions!$D$11
Name central_public_coverage_additions_growth: Assumptions!$E$11
Name central_public_coverage_additions_positive: Assumptions!$F$11
Name central_public_coverage_additions_positive_growth: Assumptions!$G$11
Name central_public_coverage_churn: Assumptions!$D$12
Name central_public_coverage_churn_growth: Assumptions!$E$12
Name central_public_coverage_churn_positive: Assumptions!$F$12
Name central_public_coverage_churn_positive_growth: Assumptions!$G$12

Sheet Assumptions
A1: Input label | B1: Named range name | C1: Unit / note | D1: Base starting value | E1: Base annual growth | F1: Positive starting value | G1: Positive annual growth
A2: Revenue inputs
A3: National Live Births Per Month | B3: national_live_births_per_month | C3: births/month | Directionally consistent with roughly 1.75 million births per year | D3: 145833 | E3: 0.018 | F3: 145833 | G3: 0.018
A4: Central Regional Opportunity Weight | B4: central_regional_opportunity_weight | C4: % of national opportunity | D4: 0.28 | E4: 0 | F4: 0.28 | G4: 0
A5: Central ANC Access Rate | B5: central_anc_access_rate | C5: % | ANC channel reach | D5: 0.72 | E5: 0.003 | F5: 0.72 | G5: 0.003
A6: Central Third Trimester Window Rate | B6: central_third_trimester_window_rate | C6: % | Share reached in relevant gestational window | D6: 0.62 | E6: 0.006 | F6: 0.62 | G6: 0.006
A7: Central Public Eligibility Rate | B7: central_public_eligibility_rate | C7: % | Funded or affordable share of reachable pregnancies | D7: 0.28 | E7: 0.08 | F7: 0.35 | G7: 0.1
A8: Central Public Provider Recommendation Rate | B8: central_public_provider_recommendation_rate | C8: % | D8: 0.56 | E8: 0.04 | F8: 0.6272 | G8: 0.05
A9: Central Public Acceptance Rate | B9: central_public_acceptance_rate | C9: % | D9: 0.78 | E9: 0.02 | F9: 0.819 | G9: 0.025
A10: Central Public Stock Availability Rate | B10: central_public_stock_availability_rate | C10: % | D10: 0.9 | E10: 0.015 | F10: 0.954 | G10: 0.02
A11: Central Public Coverage Additions | B11: central_public_coverage_additions | C11: % pts/month | Monthly rollout gain from onboarding, awareness, and funded expansion | D11: 0.025 | E11: 0.03 | F11: 0.03375 | G11: 0.04
A12: Central Public Coverage Churn | B12: central_public_coverage_churn | C12: % pts/month | Loss of active coverage due to drop-off, stock issues, and execution leakage | D12: 0.004 | E12: 0 | F12: 0.003 | G12: 0
A13: Central Public Net Realised Price Per Dose | B13: central_public_net_price_per_dose | C13: UGX/dose | D13: 35500 | E13: 0.03 | F13: 38340 | G13: 0.03
A14: Western Regional Opportunity Weight | B14: western_regional_opportunity_weight | C14: % of national opportunity | D14: 0.25 | E14: 0 | F14: 0.25 | G14: 0
... A71: Northern Private Net Realised Price Per Dose | B71: northern_private_net_price_per_dose | C71: UGX/dose | D71: 76000 | E71: 0.035 | F71: 79800 | G71: 0.035
A72: Variable cost inputs
A73: Landed Vaccine Cost Per Dose | B73: landed_vaccine_cost_per_dose | C73: UGX/dose | Leaner transfer price assumption | D73: 20500 | E73: 0.035 | F73: 19475 | G73: 0.035
A74: Import and Clearance Cost Per Dose | B74: import_clearance_cost_per_dose | C74: UGX/dose | International freight and import handling | D74: 850 | E74: 0.04 | F74: 824.5 | G74: 0.04
A75: Cold-Chain Warehousing Cost Per Dose | B75: cold_chain_warehousing_cost_per_dose | C75: UGX/dose | National warehousing and cold-chain holding | D75: 950 | E75: 0.04 | F75: 921.5 | G75: 0.04
A76: Central Public Distribution Cost Per Dose | B76: central_public_distribution_cost_per_dose | C76: UGX/dose | D76: 2500 | E76: 0.04 | F76: 2400 | G76: 0.04
A77: Western Public Distribution Cost Per Dose | B77: western_public_distribution_cost_per_dose | C77: UGX/dose | D77: 3400 | E77: 0.04 | F77: 3264 | G77: 0.04
A78: Eastern Public Distribution Cost Per Dose | B78: eastern_public_distribution_cost_per_dose | C78: UGX/dose | D78: 4200 | E78: 0.04 | F78: 4032 | G78: 0.04
A79: Northern Public Distribution Cost Per Dose | B79: northern_public_distribution_cost_per_dose | C79: UGX/dose | D79: 5600 | E79: 0.04 | F79: 5376 | G79: 0.04
A80: Central Private Distribution Cost Per Dose | B80: central_private_distribution_cost_per_dose | C80: UGX/dose | D80: 3200 | E80: 0.04 | F80: 3072 | G80: 0.04
A81: Western Private Distribution Cost Per Dose | B81: western_private_distribution_cost_per_dose | C81: UGX/dose | D81: 4300 | E81: 0.04 | F81: 4128 | G81: 0.04
A82: Eastern Private Distribution Cost Per Dose | B82: eastern_private_distribution_cost_per_dose | C82: UGX/dose | D82: 5100 | E82: 0.04 | F82: 4896 | G82: 0.04
A83: Northern Private Distribution Cost Per Dose | B83: northern_private_distribution_cost_per_dose | C83: UGX/dose | D83: 6600 | E83: 0.04 | F83: 6336 | G83: 0.04
A84: Central Public Wastage Rate | B84: central_public_wastage_rate | C84: % | D84: 0.035 | E84: 0 | F84: 0.0315 | G84: 0
... A95: Northern Private Trade Support Per Dose | B95: northern_private_trade_support_per_dose | C95: UGX/dose | D95: 1200 | E95: 0.03 | F95: 1140 | G95: 0.03
A96: Fixed cost inputs
A97: Regulatory Headcount | B97: regulatory_headcount | C97: FTE | D97: 1 | E97: 0 | F97: 1 | G97: 0
A98: Regulatory Cost Per FTE | B98: regulatory_cost_per_fte | C98: UGX/FTE/month | D98: 8500000 | E98: 0.05 | F98: 7480000 | G98: 0.05
A99: Regulatory Fees and Compliance | B99: regulatory_fees_and_compliance | C99: UGX/month | D99: 4500000 | E99: 0.04 | F99: 3960000 | G99: 0.04
A100: Market Access Headcount | B100: market_access_headcount | C100: FTE | D100: 2 | E100: 0 | F100: 2 | G100: 0
A101: Market Access Cost Per FTE | B101: market_access_cost_per_fte | C101: UGX/FTE/month | D101: 8000000 | E101: 0.05 | F101: 7040000 | G101: 0.05
A102: Tender Support Budget | B102: tender_support_budget | C102: UGX/month | D102: 5000000 | E102: 0.04 | F102: 4400000 | G102: 0.04
A103: Medical Headcount | B103: medical_headcount | C103: FTE | D103: 1 | E103: 0 | F103: 1 | G103: 0
A104: Medical Cost Per FTE | B104: medical_cost_per_fte | C104: UGX/FTE/month | D104: 9500000 | E104: 0.05 | F104: 8360000 | G104: 0.05
A105: KOL and Medical Program Budget | B105: kol_and_medical_program_budget | C105: UGX/month | D105: 6000000 | E105: 0.04 | F105: 5280000 | G105: 0.04
A106: Central Training Budget | B106: central_training_budget | C106: UGX/month | D106: 8000000 | E106: 0.03 | F106: 6000000 | G106: 0.03
...

Sheet Model - Positive
H1: Month 1 | I1: Month 2 | J1: Month 3 | K1: Month 4 | L1: Month 5 | M1: Month 6 | N1: Month 7 | O1: Month 8 | P1: Month 9 | Q1: Month 10 | R1: Month 11 | S1: Month 12 | T1: Month 13 | U1: Month 14 | V1: Month 15 | W1: Month 16 | X1: Month 17 | Y1: Month 18 | Z1: Month 19 | AA1: Month 20 | AB1: Month 21 | AC1: Month 22 | AD1: Month 23 | AE1: Month 24 | AF1: Month 25 | AG1: Month 26 | AH1: Month 27 | AI1: Month 28 | AJ1: Month 29 | AK1: Month 30 | AL1: Month 31 | AM1: Month 32 | AN1: Month 33 | AO1: Month 34 | AP1: Month 35 | AQ1: Month 36
A2: Net Profit | H2: =(H3-H110) -> -92794715 | I2: =(I3-I110) -> -88112219 | J2: =(J3-J110) -> -83219907 | K2: =(K3-K110) -> -78111037 | L2: =(L3-L110) -> -72778670 | M2: =(M3-M110) -> -67215672 | N2: =(N3-N110) -> -61414705 | O2: =(O3-O110) -> -55368223 | ... AQ2: =(AQ3-AQ110) -> 2.5207607e+08
B3: Revenue | H3: =(H4+H65) -> 26728497 | I3: =(I4+I65) -> 36784643 | J3: =(J4+J65) -> 47272383 | K3: =(K4+K65) -> 58205907 | L3: =(L4+L65) -> 69599826 | M3: =(M4+M65) -> 81469177 | N3: =(N4+N65) -> 93829439 | O3: =(O4+O65) -> 1.0669655e+08 | ... AQ3: =(AQ4+AQ65) -> 7.5455306e+08
C4: Public / Donor Revenue | H4: =(((H5+H20)+H35)+H50) -> 18362493 | I4: =(((I5+I20)+I35)+I50) -> 24539385 | J4: =(((J5+J20)+J35)+J50) -> 30984973 | K4: =(((K5+K20)+K35)+K50) -> 37708235 | L4: =(((L5+L20)+L35)+L50) -> 44718415 | M4: =(((M5+M20)+M35)+M50) -> 52025034 | N4: =(((N5+N20)+N35)+N50) -> 59637897 | O4: =(((O5+O20)+O35)+O50) -> 67567100 | ... AQ4: =(((AQ5+AQ20)+AQ35)+AQ50) -> 4.7005926e+08
D5: Central Public Revenue | H5: =(H6*H19) -> 9589290.9 | I5: =(I6*I19) -> 13562480 | J5: =(J6*J19) -> 17709319 | K5: =(K6*K19) -> 22035611 | L5: =(L6*L19) -> 26547335 | M5: =(M6*M19) -> 31250647 | N5: =(N6*N19) -> 36151886 | O5: =(O6*O19) -> 41257581 | ... AQ5: =(AQ6*AQ19) -> 3.0087064e+08
E6: Central Public Administered Doses | H6: =(((((H7*H12)*H13)*H14)*H15)*H16) -> 250.11192 | I6: =(((((I7*I12)*I13)*I14)*I15)*I16) -> 352.87204 | J6: =(((((J7*J12)*J13)*J14)*J15)*J16) -> 459.63196 | K6: =(((((K7*K12)*K13)*K14)*K15)*K16) -> 570.51056 | L6: =(((((L7*L12)*L13)*L14)*L15)*L16) -> 685.6299 | M6: =(((((M7*M12)*M13)*M14)*M15)*M16) -> 805.11526 | N6: =(((((N7*N12)*N13)*N14)*N15)*N16) -> 929.09524 | O6: =(((((O7*O12)*O13)*O14)*O15)*O16) -> 1057.7019 | ... AQ6: =(((((AQ7*AQ12)*AQ13)*AQ14)*AQ15)*AQ16) -> 7199.2257
F7: Central Reachable Pregnancies | H7: =(((H8*H9)*H10)*H11) -> 18227.958 | I7: =(((I8*I9)*I10)*I11) -> 18268.74 | J7: =(((J8*J9)*J10)*J11) -> 18309.612 | K7: =(((K8*K9)*K10)*K11) -> 18350.576 | L7: =(((L8*L9)*L10)*L11) -> 18391.632 | M7: =(((M8*M9)*M10)*M11) -> 18432.779 | N7: =(((N8*N9)*N10)*N11) -> 18474.018 | O7: =(((O8*O9)*O10)*O11) -> 18515.35 | ... AQ7: =(((AQ8*AQ9)*AQ10)*AQ11) -> 19710.949
G8: National Live Births Per Month | H8: =national_live_births_per_month_positive*(1+national_live_births_per_month_positive_growth)^((COLUMN()-8)/12) -> 145833 | I8: =national_live_births_per_month_positive*(1+national_live_births_per_month_positive_growth)^((COLUMN()-8)/12) -> 146049.97 | J8: =national_live_births_per_month_positive*(1+national_live_births_per_month_positive_growth)^((COLUMN()-8)/12) -> 146267.25 | K8: =national_live_births_per_month_positive*(1+national_live_births_per_month_positive_growth)^((COLUMN()-8)/12) -> 146484.86 | L8: =national_live_births_per_month_positive*(1+national_live_births_per_month_positive_growth)^((COLUMN()-8)/12) -> 146702.8 | M8: =national_live_births_per_month_positive*(1+national_live_births_per_month_positive_growth)^((COLUMN()-8)/12) -> 146921.06 | N8: =national_live_births_per_month_positive*(1+national_live_births_per_month_positive_growth)^((COLUMN()-8)/12) -> 147139.64 | O8: =national_live_births_per_month_positive*(1+national_live_births_per_month_positive_growth)^((COLUMN()-8)/12) -> 147358.55 | ... AQ8: =national_live_births_per_month_positive*(1+national_live_births_per_month_positive_growth)^((COLUMN()-8)/12) -> 153622.03
G9: times Central Regional Opportunity Weight | H9: =central_regional_opportunity_weight_positive*(1+central_regional_opportunity_weight_positive_growth)^((COLUMN()-8)/12) -> 0.28 | I9: =central_regional_opportunity_weight_positive*(1+central_regional_opportunity_weight_positive_growth)^((COLUMN()-8)/12) -> 0.28 | J9: =central_regional_opportunity_weight_positive*(1+central_regional_opportunity_weight_positive_growth)^((COLUMN()-8)/12) -> 0.28 | K9: =central_regional_opportunity_weight_positive*(1+central_regional_opportunity_weight_positive_growth)^((COLUMN()-8)/12) -> 0.28 | L9: =central_regional_opportunity_weight_positive*(1+central_regional_opportunity_weight_positive_growth)^((COLUMN()-8)/12) -> 0.28 | M9: =central_regional_opportunity_weight_positive*(1+central_regional_opportunity_weight_positive_growth)^((COLUMN()-8)/12) -> 0.28 | N9: =central_regional_opportunity_weight_positive*(1+central_regional_opportunity_weight_positive_growth)^((COLUMN()-8)/12) -> 0.28 | O9: =central_regional_opportunity_weight_positive*(1+central_regional_opportunity_weight_positive_growth)^((COLUMN()-8)/12) -> 0.28 | ... AQ9: =central_regional_opportunity_weight_positive*(1+central_regional_opportunity_weight_positive_growth)^((COLUMN()-8)/12) -> 0.28
G10: times Central ANC Access Rate | H10: =central_anc_access_rate_positive*(1+central_anc_access_rate_positive_growth)^((COLUMN()-8)/12) -> 0.72 | I10: =central_anc_access_rate_positive*(1+central_anc_access_rate_positive_growth)^((COLUMN()-8)/12) -> 0.72017975 | J10: =central_anc_access_rate_positive*(1+central_anc_access_rate_positive_growth)^((COLUMN()-8)/12) -> 0.72035955 | K10: =central_anc_access_rate_positive*(1+central_anc_access_rate_positive_growth)^((COLUMN()-8)/12) -> 0.72053939 | L10: =central_anc_access_rate_positive*(1+central_anc_access_rate_positive_growth)^((COLUMN()-8)/12) -> 0.72071928 | M10: =central_anc_access_rate_positive*(1+central_anc_access_rate_positive_growth)^((COLUMN()-8)/12) -> 0.72089921 | N10: =central_anc_access_rate_positive*(1+central_anc_access_rate_positive_growth)^((COLUMN()-8)/12) -> 0.72107919 | O10: =central_anc_access_rate_positive*(1+central_anc_access_rate_positive_growth)^((COLUMN()-8)/12) -> 0.72125921 | ... AQ10: =central_anc_access_rate_positive*(1+central_anc_access_rate_positive_growth)^((COLUMN()-8)/12) -> 0.72631813
G11: times Central Third Trimester Window Rate | H11: =central_third_trimester_window_rate_positive*(1+central_third_trimester_window_rate_positive_growth)^((COLUMN()-8)/12) -> 0.62 | I11: =central_third_trimester_window_rate_positive*(1+central_third_trimester_window_rate_positive_growth)^((COLUMN()-8)/12) -> 0.62030915 | J11: =central_third_trimester_window_rate_positive*(1+central_third_trimester_window_rate_positive_growth)^((COLUMN()-8)/12) -> 0.62061846 | K11: =central_third_trimester_window_rate_positive*(1+central_third_trimester_window_rate_positive_growth)^((COLUMN()-8)/12) -> 0.62092791 | L11: =central_third_trimester_window_rate_positive*(1+central_third_trimester_window_rate_positive_growth)^((COLUMN()-8)/12) -> 0.62123753 | M11: =central_third_trimester_window_rate_positive*(1+central_third_trimester_window_rate_positive_growth)^((COLUMN()-8)/12) -> 0.6215473 | N11: =central_third_trimester_window_rate_positive*(1+central_third_trimester_window_rate_positive_growth)^((COLUMN()-8)/12) -> 0.62185722 | O11: =central_third_trimester_window_rate_positive*(1+central_third_trimester_window_rate_positive_growth)^((COLUMN()-8)/12) -> 0.6221673 | ... AQ11: =central_third_trimester_window_rate_positive*(1+central_third_trimester_window_rate_positive_growth)^((COLUMN()-8)/12) -> 0.6309125
F12: times Central Public Eligibility Rate | H12: =central_public_eligibility_rate_positive*(1+central_public_eligibility_rate_positive_growth)^((COLUMN()-8)/12) -> 0.35 | I12: =central_public_eligibility_rate_positive*(1+central_public_eligibility_rate_positive_growth)^((COLUMN()-8)/12) -> 0.35279095 | J12: =central_public_eligibility_rate_positive*(1+central_public_eligibility_rate_positive_growth)^((COLUMN()-8)/12) -> 0.35560415 | K12: =central_public_eligibility_rate_positive*(1+central_public_eligibility_rate_positive_growth)^((COLUMN()-8)/12) -> 0.35843979 | L12: =central_public_eligibility_rate_positive*(1+central_public_eligibility_rate_positive_growth)^((COLUMN()-8)/12) -> 0.36129804 | M12: =central_public_eligibility_rate_positive*(1+central_public_eligibility_rate_positive_growth)^((COLUMN()-8)/12) -> 0.36417908 | N12: =central_public_eligibility_rate_positive*(1+central_public_eligibility_rate_positive_growth)^((COLUMN()-8)/12) -> 0.3670831 | O12: =central_public_eligibility_rate_positive*(1+central_public_eligibility_rate_positive_growth)^((COLUMN()-8)/12) -> 0.37001027 | ... AQ12: =central_public_eligibility_rate_positive*(1+central_public_eligibility_rate_positive_growth)^((COLUMN()-8)/12) -> 0.46216463
F13: times Central Public Provider Recommendation Rate | H13: =central_public_provider_recommendation_rate_positive*(1+central_public_provider_recommendation_rate_positive_growth)^((COLUMN()-8)/12) -> 0.6272 | I13: =central_public_provider_recommendation_rate_positive*(1+central_public_provider_recommendation_rate_positive_growth)^((COLUMN()-8)/12) -> 0.62975529 | J13: =central_public_provider_recommendation_rate_positive*(1+central_public_provider_recommendation_rate_positive_growth)^((COLUMN()-8)/12) -> 0.63232099 | K13: =central_public_provider_recommendation_rate_positive*(1+central_public_provider_recommendation_rate_positive_growth)^((COLUMN()-8)/12) -> 0.63489715 | L13: =central_public_provider_recommendation_rate_positive*(1+central_public_provider_recommendation_rate_positive_growth)^((COLUMN()-8)/12) -> 0.63748379 | M13: =central_public_provider_recommendation_rate_positive*(1+central_public_provider_recommendation_rate_positive_growth)^((COLUMN()-8)/12) -> 0.64008098 | N13: =central_public_provider_recommendation_rate_positive*(1+central_public_provider_recommendation_rate_positive_growth)^((COLUMN()-8)/12) -> 0.64268875 | O13: =central_public_provider_recommendation_rate_positive*(1+central_public_provider_recommendation_rate_positive_growth)^((COLUMN()-8)/12) -> 0.64530715 | ... AQ13: =central_public_provider_recommendation_rate_positive*(1+central_public_provider_recommendation_rate_positive_growth)^((COLUMN()-8)/12) -> 0.72311633
F14: times Central Public Acceptance Rate | H14: =central_public_acceptance_rate_positive*(1+central_public_acceptance_rate_positive_growth)^((COLUMN()-8)/12) -> 0.819 | I14: =central_public_acceptance_rate_positive*(1+central_public_acceptance_rate_positive_growth)^((COLUMN()-8)/12) -> 0.82068701 | J14: =central_public_acceptance_rate_positive*(1+central_public_acceptance_rate_positive_growth)^((COLUMN()-8)/12) -> 0.82237749 | K14: =central_public_acceptance_rate_positive*(1+central_public_acceptance_rate_positive_growth)^((COLUMN()-8)/12) -> 0.82407145 | L14: =central_public_acceptance_rate_positive*(1+central_public_acceptance_rate_positive_growth)^((COLUMN()-8)/12) -> 0.8257689 | M14: =central_public_acceptance_rate_positive*(1+central_public_acceptance_rate_positive_growth)^((COLUMN()-8)/12) -> 0.82746985 | N14: =central_public_acceptance_rate_positive*(1+central_public_acceptance_rate_positive_growth)^((COLUMN()-8)/12) -> 0.8291743 | O14: =central_public_acceptance_rate_positive*(1+central_public_acceptance_rate_positive_growth)^((COLUMN()-8)/12) -> 0.83088227 | ... AQ14: =central_public_acceptance_rate_positive*(1+central_public_acceptance_rate_positive_growth)^((COLUMN()-8)/12) -> 0.88016044
F15: times Central Public Stock Availability Rate | H15: =central_public_stock_availability_rate_positive*(1+central_public_stock_availability_rate_positive_growth)^((COLUMN()-8)/12) -> 0.954 | I15: =central_public_stock_availability_rate_positive*(1+central_public_stock_availability_rate_positive_growth)^((COLUMN()-8)/12) -> 0.95557561 | J15: =central_public_stock_availability_rate_positive*(1+central_public_stock_availability_rate_positive_growth)^((COLUMN()-8)/12) -> 0.95715382 | K15: =central_public_stock_availability_rate_positive*(1+central_public_stock_availability_rate_positive_growth)^((COLUMN()-8)/12) -> 0.95873464 | L15: =central_public_stock_availability_rate_positive*(1+central_public_stock_availability_rate_positive_growth)^((COLUMN()-8)/12) -> 0.96031806 | M15: =central_public_stock_availability_rate_positive*(1+central_public_stock_availability_rate_positive_growth)^((COLUMN()-8)/12) -> 0.96190411 | N15: =central_public_stock_availability_rate_positive*(1+central_public_stock_availability_rate_positive_growth)^((COLUMN()-8)/12) -> 0.96349277 | O15: =central_public_stock_availability_rate_positive*(1+central_public_stock_availability_rate_positive_growth)^((COLUMN()-8)/12) -> 0.96508406 | ... AQ15: =central_public_stock_availability_rate_positive*(1+central_public_stock_availability_rate_positive_growth)^((COLUMN()-8)/12) -> 1.0107231
F16: times Central Public Active Coverage State | H16: =0.08 -> 0.08 | I16: =H16+I17-I18 -> 0.11086049 | J16: =I16+J17-J18 -> 0.14183183 | K16: =J16+K17-K18 -> 0.17291438 | L16: =K16+L17-L18 -> 0.20410851 | M16: =L16+M17-M18 -> 0.23541458 | N16: =M16+N17-N18 -> 0.26683296 | O16: =N16+O17-O18 -> 0.29836402 | P16: =O16+P17-P18 -> 0.33000813 | ... AQ16: =AP16+AQ17-AQ18 -> 1.2285117
G17: Central Public Coverage Additions | H17: =central_public_coverage_additions_positive*(1+central_public_coverage_additions_positive_growth)^((COLUMN()-8)/12) -> 0.03375 | I17: =central_public_coverage_additions_positive*(1+central_public_coverage_additions_positive_growth)^((COLUMN()-8)/12) -> 0.033860489 | J17: =central_public_coverage_additions_positive*(1+central_public_coverage_additions_positive_growth)^((COLUMN()-8)/12) -> 0.033971339 | K17: =central_public_coverage_additions_positive*(1+central_public_coverage_additions_positive_growth)^((COLUMN()-8)/12) -> 0.034082552 | L17: =central_public_coverage_additions_positive*(1+central_public_coverage_additions_positive_growth)^((COLUMN()-8)/12) -> 0.03419413 | M17: =central_public_coverage_additions_positive*(1+central_public_coverage_additions_positive_growth)^((COLUMN()-8)/12) -> 0.034306073 | N17: =central_public_coverage_additions_positive*(1+central_public_coverage_additions_positive_growth)^((COLUMN()-8)/12) -> 0.034418382 | O17: =central_public_coverage_additions_positive*(1+central_public_coverage_additions_positive_growth)^((COLUMN()-8)/12) -> 0.034531059 | ... AQ17: =central_public_coverage_additions_positive*(1+central_public_coverage_additions_positive_growth)^((COLUMN()-8)/12) -> 0.037840281
G18: plus Central Public Coverage Churn | H18: =central_public_coverage_churn_positive*(1+central_public_coverage_churn_positive_growth)^((COLUMN()-8)/12) -> 0.003 | I18: =central_public_coverage_churn_positive*(1+central_public_coverage_churn_positive_growth)^((COLUMN()-8)/12) -> 0.003 | J18: =central_public_coverage_churn_positive*(1+central_public_coverage_churn_positive_growth)^((COLUMN()-8)/12) -> 0.003 | K18: =central_public_coverage_churn_positive*(1+central_public_coverage_churn_positive_growth)^((COLUMN()-8)/12) -> 0.003 | L18: =central_public_coverage_churn_positive*(1+central_public_coverage_churn_positive_growth)^((COLUMN()-8)/12) -> 0.003 | M18: =central_public_coverage_churn_positive*(1+central_public_coverage_churn_positive_growth)^((COLUMN()-8)/12) -> 0.003 | N18: =central_public_coverage_churn_positive*(1+central_public_coverage_churn_positive_growth)^((COLUMN()-8)/12) -> 0.003 | O18: =central_public_coverage_churn_positive*(1+central_public_coverage_churn_positive_growth)^((COLUMN()-8)/12) -> 0.003 | ... AQ18: =central_public_coverage_churn_positive*(1+central_public_coverage_churn_positive_growth)^((COLUMN()-8)/12) -> 0.003
E19: times Central Public Net Realised Price Per Dose | H19: =central_public_net_price_per_dose_positive*(1+central_public_net_price_per_dose_positive_growth)^((COLUMN()-8)/12) -> 38340 | I19: =central_public_net_price_per_dose_positive*(1+central_public_net_price_per_dose_positive_growth)^((COLUMN()-8)/12) -> 38434.557 | J19: =central_public_net_price_per_dose_positive*(1+central_public_net_price_per_dose_positive_growth)^((COLUMN()-8)/12) -> 38529.347 | K19: =central_public_net_price_per_dose_positive*(1+central_public_net_price_per_dose_positive_growth)^((COLUMN()-8)/12) -> 38624.371 | L19: =central_public_net_price_per_dose_positive*(1+central_public_net_price_per_dose_positive_growth)^((COLUMN()-8)/12) -> 38719.629 | M19: =central_public_net_price_per_dose_positive*(1+central_public_net_price_per_dose_positive_growth)^((COLUMN()-8)/12) -> 38815.122 | N19: =central_public_net_price_per_dose_positive*(1+central_public_net_price_per_dose_positive_growth)^((COLUMN()-8)/12) -> 38910.85 | O19: =central_public_net_price_per_dose_positive*(1+central_public_net_price_per_dose_positive_growth)^((COLUMN()-8)/12) -> 39006.815 | ... AQ19: =central_public_net_price_per_dose_positive*(1+central_public_net_price_per_dose_positive_growth)^((COLUMN()-8)/12) -> 41792.083
D20: plus Western Public Revenue | H20: =(H21*H34) -> 4525802.9 | I20: =(I21*I34) -> 5853583.8 | J20: =(J21*J34) -> 7238911.7 | K20: =(K21*K34) -> 8683708.1 | L20: =(L21*L34) -> 10189952 | M20: =(M21*M34) -> 11759682 | N20: =(N21*N34) -> 13394997 | O20: =(O21*O34) -> 15098059 | ... AQ20: =(AQ21*AQ34) -> 1.0143103e+08
E21: Western Public Administered Doses | H21: =(((((H22*H27)*H28)*H29)*H30)*H31) -> 121.46546 | I21: =(((((I22*I27)*I28)*I29)*I30)*I31) -> 156.71451 | J21: =(((((J22*J27)*J28)*J29)*J30)*J31) -> 193.32628 | K21: =(((((K22*K27)*K28)*K29)*K30)*K31) -> 231.34124 | L21: =(((((L22*L27)*L28)*L29)*L30)*L31) -> 270.80097 | M21: =(((((M22*M27)*M28)*M29)*M30)*M31) -> 311.74816 | N21: =(((((N22*N27)*N28)*N29)*N30)*N31) -> 354.2266 | O21: =(((((O22*O27)*O28)*O29)*O30)*O31) -> 398.28127 | ... AQ21: =(((((AQ22*AQ27)*AQ28)*AQ29)*AQ30)*AQ31) -> 2497.3884
F22: Western Reachable Pregnancies | H22: =(((H23*H24)*H25)*H26) -> 13474.969 | I22: =(((I23*I24)*I25)*I26) -> 13505.117 | J22: =(((J23*J24)*J25)*J26) -> 13535.331 | K22: =(((K23*K24)*K25)*K26) -> 13565.614 | L22: =(((L23*L24)*L25)*L26) -> 13595.964 | M22: =(((M23*M24)*M25)*M26) -> 13626.382 | N22: =(((N23*N24)*N25)*N26) -> 13656.868 | O22: =(((O23*O24)*O25)*O26) -> 13687.423 | ... AQ22: =(((AQ23*AQ24)*AQ25)*AQ26) -> 14571.266
G23: National Live Births Per Month | H23: =H8 -> 145833 | I23: =I8 -> 146049.97 | J23: =J8 -> 146267.25 | K23: =K8 -> 146484.86 | L23: =L8 -> 146702.8 | M23: =M8 -> 146921.06 | N23: =N8 -> 147139.64 | O23: =O8 -> 147358.55 | ... AQ23: =AQ8 -> 153622.03
G24: times Western Regional Opportunity Weight | H24: =western_regional_opportunity_weight_positive*(1+western_regional_opportunity_weight_positive_growth)^((COLUMN()-8)/12) -> 0.25 | I24: =western_regional_opportunity_weight_positive*(1+western_regional_opportunity_weight_positive_growth)^((COLUMN()-8)/12) -> 0.25 | J24: =western_regional_opportunity_weight_positive*(1+western_regional_opportunity_weight_positive_growth)^((COLUMN()-8)/12) -> 0.25 | K24: =western_regional_opportunity_weight_positive*(1+western_regional_opportunity_weight_positive_growth)^((COLUMN()-8)/12) -> 0.25 | L24: =western_regional_opportunity_weight_positive*(1+western_regional_opportunity_weight_positive_growth)^((COLUMN()-8)/12) -> 0.25 | M24: =western_regional_opportunity_weight_positive*(1+western_regional_opportunity_weight_positive_growth)^((COLUMN()-8)/12) -> 0.25 | N24: =western_regional_opportunity_weight_positive*(1+western_regional_opportunity_weight_positive_growth)^((COLUMN()-8)/12) -> 0.25 | O24: =western_regional_opportunity_weight_positive*(1+western_regional_opportunity_weight_positive_growth)^((COLUMN()-8)/12) -> 0.25 | ... AQ24: =western_regional_opportunity_weight_positive*(1+western_regional_opportunity_weight_positive_growth)^((COLUMN()-8)/12) -> 0.25
G25: times Western ANC Access Rate | H25: =western_anc_access_rate_positive*(1+western_anc_access_rate_positive_growth)^((COLUMN()-8)/12) -> 0.66 | I25: =western_anc_access_rate_positive*(1+western_anc_access_rate_positive_growth)^((COLUMN()-8)/12) -> 0.66016477 | J25: =western_anc_access_rate_positive*(1+western_anc_access_rate_positive_growth)^((COLUMN()-8)/12) -> 0.66032959 | K25: =western_anc_access_rate_positive*(1+western_anc_access_rate_positive_growth)^((COLUMN()-8)/12) -> 0.66049444 | L25: =western_anc_access_rate_positive*(1+western_anc_access_rate_positive_growth)^((COLUMN()-8)/12) -> 0.66065934 | M25: =western_anc_access_rate_positive*(1+western_anc_access_rate_positive_growth)^((COLUMN()-8)/12) -> 0.66082428 | N25: =western_anc_access_rate_positive*(1+western_anc_access_rate_positive_growth)^((COLUMN()-8)/12) -> 0.66098926 | O25: =western_anc_access_rate_positive*(1+western_anc_access_rate_positive_growth)^((COLUMN()-8)/12) -> 0.66115428 | ... AQ25: =western_anc_access_rate_positive*(1+western_anc_access_rate_positive_growth)^((COLUMN()-8)/12) -> 0.66579162
G26: times Western Third Trimester Window Rate | H26: =western_third_trimester_window_rate_positive*(1+western_third_trimester_window_rate_positive_growth)^((COLUMN()-8)/12) -> 0.56 | I26: =western_third_trimester_window_rate_positive*(1+western_third_trimester_window_rate_positive_growth)^((COLUMN()-8)/12) -> 0.56027923 | J26: =western_third_trimester_window_rate_positive*(1+western_third_trimester_window_rate_positive_growth)^((COLUMN()-8)/12) -> 0.56055861 | K26: =western_third_trimester_window_rate_positive*(1+western_third_trimester_window_rate_positive_growth)^((COLUMN()-8)/12) -> 0.56083812 | L26: =western_third_trimester_window_rate_positive*(1+western_third_trimester_window_rate_positive_growth)^((COLUMN()-8)/12) -> 0.56111777 | M26: =western_third_trimester_window_rate_positive*(1+western_third_trimester_window_rate_positive_growth)^((COLUMN()-8)/12) -> 0.56139756 | N26: =western_third_trimester_window_rate_positive*(1+western_third_trimester_window_rate_positive_growth)^((COLUMN()-8)/12) -> 0.56167749 | O26: =western_third_trimester_window_rate_positive*(1+western_third_trimester_window_rate_positive_growth)^((COLUMN()-8)/12) -> 0.56195756 | ... AQ26: =western_third_trimester_window_rate_positive*(1+western_third_trimester_window_rate_positive_growth)^((COLUMN()-8)/12) -> 0.56985645
F27: times Western Public Eligibility Rate | H27: =western_public_eligibility_rate_positive*(1+western_public_eligibility_rate_positive_growth)^((COLUMN()-8)/12) -> 0.275 | I27: =western_public_eligibility_rate_positive*(1+western_public_eligibility_rate_positive_growth)^((COLUMN()-8)/12) -> 0.27719289 | J27: =western_public_eligibility_rate_positive*(1+western_public_eligibility_rate_positive_growth)^((COLUMN()-8)/12) -> 0.27940326 | K27: =western_public_eligibility_rate_positive*(1+western_public_eligibility_rate_positive_growth)^((COLUMN()-8)/12) -> 0.28163126 | L27: =western_public_eligibility_rate_positive*(1+western_public_eligibility_rate_positive_growth)^((COLUMN()-8)/12) -> 0.28387703 | M27: =western_public_eligibility_rate_positive*(1+western_public_eligibility_rate_positive_growth)^((COLUMN()-8)/12) -> 0.28614071 | N27: =western_public_eligibility_rate_positive*(1+western_public_eligibility_rate_positive_growth)^((COLUMN()-8)/12) -> 0.28842243 | O27: =western_public_eligibility_rate_positive*(1+western_public_eligibility_rate_positive_growth)^((COLUMN()-8)/12) -> 0.29072235 | ... AQ27: =western_public_eligibility_rate_positive*(1+western_public_eligibility_rate_positive_growth)^((COLUMN()-8)/12) -> 0.36312936
F28: times Western Public Provider Recommendation Rate | H28: =western_public_provider_recommendation_rate_positive*(1+western_public_provider_recommendation_rate_positive_growth)^((COLUMN()-8)/12) -> 0.5488 | I28: =western_public_provider_recommendation_rate_positive*(1+western_public_provider_recommendation_rate_positive_growth)^((COLUMN()-8)/12) -> 0.55103588 | J28: =western_public_provider_recommendation_rate_positive*(1+western_public_provider_recommendation_rate_positive_growth)^((COLUMN()-8)/12) -> 0.55328087 | K28: =western_public_provider_recommendation_rate_positive*(1+western_public_provider_recommendation_rate_positive_growth)^((COLUMN()-8)/12) -> 0.555535 | L28: =western_public_provider_recommendation_rate_positive*(1+western_public_provider_recommendation_rate_positive_growth)^((COLUMN()-8)/12) -> 0.55779832 | M28: =western_public_provider_recommendation_rate_positive*(1+western_public_provider_recommendation_rate_positive_growth)^((COLUMN()-8)/12) -> 0.56007086 | N28: =western_public_provider_recommendation_rate_positive*(1+western_public_provider_recommendation_rate_positive_growth)^((COLUMN()-8)/12) -> 0.56235266 | O28: =western_public_provider_recommendation_rate_positive*(1+western_public_provider_recommendation_rate_positive_growth)^((COLUMN()-8)/12) -> 0.56464375 | ... AQ28: =western_public_provider_recommendation_rate_positive*(1+western_public_provider_recommendation_rate_positive_growth)^((COLUMN()-8)/12) -> 0.63272679
F29: times Western Public Acceptance Rate | H29: =western_public_acceptance_rate_positive*(1+western_public_acceptance_rate_positive_growth)^((COLUMN()-8)/12) -> 0.819 | I29: =western_public_acceptance_rate_positive*(1+western_public_acceptance_rate_positive_growth)^((COLUMN()-8)/12) -> 0.82068701 | J29: =western_public_acceptance_rate_positive*(1+western_public_acceptance_rate_positive_growth)^((COLUMN()-8)/12) -> 0.82237749 | K29: =western_public_acceptance_rate_positive*(1+western_public_acceptance_rate_positive_growth)^((COLUMN()-8)/12) -> 0.82407145 | L29: =western_public_acceptance_rate_positive*(1+western_public_acceptance_rate_positive_growth)^((COLUMN()-8)/12) -> 0.8257689 | M29: =western_public_acceptance_rate_positive*(1+western_public_acceptance_rate_positive_growth)^((COLUMN()-8)/12) -> 0.82746985 | N29: =western_public_acceptance_rate_positive*(1+western_public_acceptance_rate_positive_growth)^((COLUMN()-8)/12) -> 0.8291743 | O29: =western_public_acceptance_rate_positive*(1+western_public_acceptance_rate_positive_growth)^((COLUMN()-8)/12) -> 0.83088227 | ... AQ29: =western_public_acceptance_rate_positive*(1+western_public_acceptance_rate_positive_growth)^((COLUMN()-8)/12) -> 0.88016044
F30: times Western Public Stock Availability Rate | H30: =western_public_stock_availability_rate_positive*(1+western_public_stock_availability_rate_positive_growth)^((COLUMN()-8)/12) -> 0.9116 | I30: =western_public_stock_availability_rate_positive*(1+western_public_stock_availability_rate_positive_growth)^((COLUMN()-8)/12) -> 0.91310558 | J30: =western_public_stock_availability_rate_positive*(1+western_public_stock_availability_rate_positive_growth)^((COLUMN()-8)/12) -> 0.91461365 | K30: =western_public_stock_availability_rate_positive*(1+western_public_stock_availability_rate_positive_growth)^((COLUMN()-8)/12) -> 0.91612421 | L30: =western_public_stock_availability_rate_positive*(1+western_public_stock_availability_rate_positive_growth)^((COLUMN()-8)/12) -> 0.91763726 | M30: =western_public_stock_availability_rate_positive*(1+western_public_stock_availability_rate_positive_growth)^((COLUMN()-8)/12) -> 0.91915281 | N30: =western_public_stock_availability_rate_positive*(1+western_public_stock_availability_rate_positive_growth)^((COLUMN()-8)/12) -> 0.92067087 | O30: =western_public_stock_availability_rate_positive*(1+western_public_stock_availability_rate_positive_growth)^((COLUMN()-8)/12) -> 0.92219143 | ... AQ30: =western_public_stock_availability_rate_positive*(1+western_public_stock_availability_rate_positive_growth)^((COLUMN()-8)/12) -> 0.96580211
F31: times Western Public Active Coverage State | H31: =0.08 -> 0.08 | I31: =H31+I32-I33 -> 0.10137955 | J31: =I31+J32-J33 -> 0.12283892 | K31: =J31+K32-K33 -> 0.14437835 | L31: =K31+L32-L33 -> 0.16599813 | M31: =L31+M32-M33 -> 0.1876985 | N31: =M31+N32-N33 -> 0.20947973 | O31: =N31+O32-O33 -> 0.2313421 | P31: =O31+P32-P33 -> 0.25328585 | ... AQ31: =AP31+AQ32-AQ33 -> 0.87752846
G32: Western Public Coverage Additions | H32: =western_public_coverage_additions_positive*(1+western_public_coverage_additions_positive_growth)^((COLUMN()-8)/12) -> 0.0243 | I32: =western_public_coverage_additions_positive*(1+western_public_coverage_additions_positive_growth)^((COLUMN()-8)/12) -> 0.024379552 | J32: =western_public_coverage_additions_positive*(1+western_public_coverage_additions_positive_growth)^((COLUMN()-8)/12) -> 0.024459364 | K32: =western_public_coverage_additions_positive*(1+western_public_coverage_additions_positive_growth)^((COLUMN()-8)/12) -> 0.024539438 | L32: =western_public_coverage_additions_positive*(1+western_public_coverage_additions_positive_growth)^((COLUMN()-8)/12) -> 0.024619774 | M32: =western_public_coverage_additions_positive*(1+western_public_coverage_additions_positive_growth)^((COLUMN()-8)/12) -> 0.024700372 | N32: =western_public_coverage_additions_positive*(1+western_public_coverage_additions_positive_growth)^((COLUMN()-8)/12) -> 0.024781235 | O32: =western_public_coverage_additions_positive*(1+western_public_coverage_additions_positive_growth)^((COLUMN()-8)/12) -> 0.024862362 | ... AQ32: =western_public_coverage_additions_positive*(1+western_public_coverage_additions_positive_growth)^((COLUMN()-8)/12) -> 0.027245002
G33: plus Western Public Coverage Churn | H33: =western_public_coverage_churn_positive*(1+western_public_coverage_churn_positive_growth)^((COLUMN()-8)/12) -> 0.003 | I33: =western_public_coverage_churn_positive*(1+western_public_coverage_churn_positive_growth)^((COLUMN()-8)/12) -> 0.003 | J33: =western_public_coverage_churn_positive*(1+western_public_coverage_churn_positive_growth)^((COLUMN()-8)/12) -> 0.003 | K33: =western_public_coverage_churn_positive*(1+western_public_coverage_churn_positive_growth)^((COLUMN()-8)/12) -> 0.003 | L33: =western_public_coverage_churn_positive*(1+western_public_coverage_churn_positive_growth)^((COLUMN()-8)/12) -> 0.003 | M33: =western_public_coverage_churn_positive*(1+western_public_coverage_churn_positive_growth)^((COLUMN()-8)/12) -> 0.003 | N33: =western_public_coverage_churn_positive*(1+western_public_coverage_churn_positive_growth)^((COLUMN()-8)/12) -> 0.003 | O33: =western_public_coverage_churn_positive*(1+western_public_coverage_churn_positive_growth)^((COLUMN()-8)/12) -> 0.003 | ... AQ33: =western_public_coverage_churn_positive*(1+western_public_coverage_churn_positive_growth)^((COLUMN()-8)/12) -> 0.003
E34: times Western Public Net Realised Price Per Dose | H34: =western_public_net_price_per_dose_positive*(1+western_public_net_price_per_dose_positive_growth)^((COLUMN()-8)/12) -> 37260 | I34: =western_public_net_price_per_dose_positive*(1+western_public_net_price_per_dose_positive_growth)^((COLUMN()-8)/12) -> 37351.893 | J34: =western_public_net_price_per_dose_positive*(1+western_public_net_price_per_dose_positive_growth)^((COLUMN()-8)/12) -> 37444.013 | K34: =western_public_net_price_per_dose_positive*(1+western_public_net_price_per_dose_positive_growth)^((COLUMN()-8)/12) -> 37536.36 | L34: =western_public_net_price_per_dose_positive*(1+western_public_net_price_per_dose_positive_growth)^((COLUMN()-8)/12) -> 37628.935 | M34: =western_public_net_price_per_dose_positive*(1+western_public_net_price_per_dose_positive_growth)^((COLUMN()-8)/12) -> 37721.738 | N34: =western_public_net_price_per_dose_positive*(1+western_public_net_price_per_dose_positive_growth)^((COLUMN()-8)/12) -> 37814.77 | O34: =western_public_net_price_per_dose_positive*(1+western_public_net_price_per_dose_positive_growth)^((COLUMN()-8)/12) -> 37908.031 | ... AQ34: =western_public_net_price_per_dose_positive*(1+western_public_net_price_per_dose_positive_growth)^((COLUMN()-8)/12) -> 40614.841
D35: plus Eastern Public Revenue | H35: =(H36*H49) -> 2769509.5 | I35: =(I36*I49) -> 3390606.7 | J35: =(J36*J49) -> 4038383.6 | K35: =(K36*K49) -> 4713730.2 | L35: =(L36*L49) -> 5417563.1 | M35: =(M36*M49) -> 6150826.2 | N35: =(N36*N49) -> 6914491.8 | O35: =(O36*O49) -> 7709560.9 | ... AQ35: =(AQ36*AQ49) -> 47883301
E36: Eastern Public Administered Doses | H36: =(((((H37*H42)*H43)*H44)*H45)*H46) -> 76.548078 | I36: =(((((I37*I42)*I43)*I44)*I45)*I46) -> 93.484387 | J36: =(((((J37*J42)*J43)*J44)*J45)*J46) -> 111.07069 | K36: =(((((K37*K42)*K43)*K44)*K45)*K46) -> 129.3263 | L36: =(((((L37*L42)*L43)*L44)*L45)*L46) -> 148.27104 | M36: =(((((M37*M42)*M43)*M44)*M45)*M46) -> 167.92527 | N36: =(((((N37*N42)*N43)*N44)*N45)*N46) -> 188.30987 | O36: =(((((O37*O42)*O43)*O44)*O45)*O46) -> 209.4463 | ... AQ36: =(((((AQ37*AQ42)*AQ43)*AQ44)*AQ45)*AQ46) -> 1214.1536
F37: Eastern Reachable Pregnancies | H37: =(((H38*H39)*H40)*H41) -> 11484.349 | I37: =(((I38*I39)*I40)*I41) -> 11510.043 | J37: =(((J38*J39)*J40)*J41) -> 11535.794 | K37: =(((K38*K39)*K40)*K41) -> 11561.603 | L37: =(((L38*L39)*L40)*L41) -> 11587.469 | M37: =(((M38*M39)*M40)*M41) -> 11613.394 | N37: =(((N38*N39)*N40)*N41) -> 11639.377 | O37: =(((O38*O39)*O40)*O41) -> 11665.417 | ... AQ37: =(((AQ38*AQ39)*AQ40)*AQ41) -> 12418.693
G38: National Live Births Per Month | H38: =H8 -> 145833 | I38: =I8 -> 146049.97 | J38: =J8 -> 146267.25 | K38: =K8 -> 146484.86 | L38: =L8 -> 146702.8 | M38: =M8 -> 146921.06 | N38: =N8 -> 147139.64 | O38: =O8 -> 147358.55 | ... AQ38: =AQ8 -> 153622.03
G39: times Eastern Regional Opportunity Weight | H39: =eastern_regional_opportunity_weight_positive*(1+eastern_regional_opportunity_weight_positive_growth)^((COLUMN()-8)/12) -> 0.25 | I39: =eastern_regional_opportunity_weight_positive*(1+eastern_regional_opportunity_weight_positive_growth)^((COLUMN()-8)/12) -> 0.25 | J39: =eastern_regional_opportunity_weight_positive*(1+eastern_regional_opportunity_weight_positive_growth)^((COLUMN()-8)/12) -> 0.25 | K39: =eastern_regional_opportunity_weight_positive*(1+eastern_regional_opportunity_weight_positive_growth)^((COLUMN()-8)/12) -> 0.25 | L39: =eastern_regional_opportunity_weight_positive*(1+eastern_regional_opportunity_weight_positive_growth)^((COLUMN()-8)/12) -> 0.25 | M39: =eastern_regional_opportunity_weight_positive*(1+eastern_regional_opportunity_weight_positive_growth)^((COLUMN()-8)/12) -> 0.25 | N39: =eastern_regional_opportunity_weight_positive*(1+eastern_regional_opportunity_weight_positive_growth)^((COLUMN()-8)/12) -> 0.25 | O39: =eastern_regional_opportunity_weight_positive*(1+eastern_regional_opportunity_weight_positive_growth)^((COLUMN()-8)/12) -> 0.25 | ... AQ39: =eastern_regional_opportunity_weight_positive*(1+eastern_regional_opportunity_weight_positive_growth)^((COLUMN()-8)/12) -> 0.25
G40: times Eastern ANC Access Rate | H40: =eastern_anc_access_rate_positive*(1+eastern_anc_access_rate_positive_growth)^((COLUMN()-8)/12) -> 0.63 | I40: =eastern_anc_access_rate_positive*(1+eastern_anc_access_rate_positive_growth)^((COLUMN()-8)/12) -> 0.63015728 | J40: =eastern_anc_access_rate_positive*(1+eastern_anc_access_rate_positive_growth)^((COLUMN()-8)/12) -> 0.63031461 | K40: =eastern_anc_access_rate_positive*(1+eastern_anc_access_rate_positive_growth)^((COLUMN()-8)/12) -> 0.63047197 | L40: =eastern_anc_access_rate_positive*(1+eastern_anc_access_rate_positive_growth)^((COLUMN()-8)/12) -> 0.63062937 | M40: =eastern_anc_access_rate_positive*(1+eastern_anc_access_rate_positive_growth)^((COLUMN()-8)/12) -> 0.63078681 | N40: =eastern_anc_access_rate_positive*(1+eastern_anc_access_rate_positive_growth)^((COLUMN()-8)/12) -> 0.63094429 | O40: =eastern_anc_access_rate_positive*(1+eastern_anc_access_rate_positive_growth)^((COLUMN()-8)/12) -> 0.63110181 | ... AQ40: =eastern_anc_access_rate_positive*(1+eastern_anc_access_rate_positive_growth)^((COLUMN()-8)/12) -> 0.63552836
...

Sheet Model - Base
H1: Month 1 | I1: Month 2 | J1: Month 3 | K1: Month 4 | L1: Month 5 | M1: Month 6 | N1: Month 7 | O1: Month 8 | P1: Month 9 | Q1: Month 10 | R1: Month 11 | S1: Month 12 | T1: Month 13 | U1: Month 14 | V1: Month 15 | W1: Month 16 | X1: Month 17 | Y1: Month 18 | Z1: Month 19 | AA1: Month 20 | AB1: Month 21 | AC1: Month 22 | AD1: Month 23 | AE1: Month 24 | AF1: Month 25 | AG1: Month 26 | AH1: Month 27 | AI1: Month 28 | AJ1: Month 29 | AK1: Month 30 | AL1: Month 31 | AM1: Month 32 | AN1: Month 33 | AO1: Month 34 | AP1: Month 35 | AQ1: Month 36
A2: Net Profit | H2: =(H3-H110) -> -1.189574e+08 | I2: =(I3-I110) -> -1.1765295e+08 | J2: =(J3-J110) -> -1.1629043e+08 | K2: =(K3-K110) -> -1.1486827e+08 | L2: =(L3-L110) -> -1.1338486e+08 | M2: =(M3-M110) -> -1.1183857e+08 | N2: =(N3-N110) -> -1.1022772e+08 | O2: =(O3-O110) -> -1.0855058e+08 | ... AQ2: =(AQ3-AQ110) -> -26265851
B3: Revenue | H3: =(H4+H65) -> 16088066 | I3: =(I4+I65) -> 20075532 | J3: =(J4+J65) -> 24206013 | K3: =(K4+K65) -> 28483455 | L3: =(L4+L65) -> 32911903 | M3: =(M4+M65) -> 37495503 | N3: =(N4+N65) -> 42238502 | O3: =(O4+O65) -> 47145251 | ... AQ3: =(AQ4+AQ65) -> 2.7251377e+08
C4: Public / Donor Revenue | H4: =(((H5+H20)+H35)+H50) -> 10911506 | I4: =(((I5+I20)+I35)+I50) -> 13396763 | J4: =(((J5+J20)+J35)+J50) -> 15972451 | K4: =(((K5+K20)+K35)+K50) -> 18641109 | L4: =(((L5+L20)+L35)+L50) -> 21405340 | M4: =(((M5+M20)+M35)+M50) -> 24267811 | N4: =(((N5+N20)+N35)+N50) -> 27231259 | O4: =(((O5+O20)+O35)+O50) -> 30298487 | ... AQ4: =(((AQ5+AQ20)+AQ35)+AQ50) -> 1.7221555e+08
D5: Central Public Revenue | H5: =(H6*H19) -> 5698224.3 | I5: =(I6*I19) -> 7323801.5 | J5: =(J6*J19) -> 9008844.3 | K5: =(K6*K19) -> 10755022 | L5: =(L6*L19) -> 12564046 | M5: =(M6*M19) -> 14437670 | N5: =(N6*N19) -> 16377693 | O5: =(O6*O19) -> 18385958 | ... AQ5: =(AQ6*AQ19) -> 1.1145827e+08
E6: Central Public Administered Doses | H6: =(((((H7*H12)*H13)*H14)*H15)*H16) -> 160.51336 | I6: =(((((I7*I12)*I13)*I14)*I15)*I16) -> 205.79672 | J6: =(((((J7*J12)*J13)*J14)*J15)*J16) -> 252.52315 | K6: =(((((K7*K12)*K13)*K14)*K15)*K16) -> 300.72785 | L6: =(((((L7*L12)*L13)*L14)*L15)*L16) -> 350.44679 | M6: =(((((M7*M12)*M13)*M14)*M15)*M16) -> 401.71673 | N6: =(((((N7*N12)*N13)*N14)*N15)*N16) -> 454.57523 | O6: =(((((O7*O12)*O13)*O14)*O15)*O16) -> 509.06064 | ... AQ6: =(((((AQ7*AQ12)*AQ13)*AQ14)*AQ15)*AQ16) -> 2880.3287
F7: Central Reachable Pregnancies | H7: =(((H8*H9)*H10)*H11) -> 18227.958 | I7: =(((I8*I9)*I10)*I11) -> 18268.74 | J7: =(((J8*J9)*J10)*J11) -> 18309.612 | K7: =(((K8*K9)*K10)*K11) -> 18350.576 | L7: =(((L8*L9)*L10)*L11) -> 18391.632 | M7: =(((M8*M9)*M10)*M11) -> 18432.779 | N7: =(((N8*N9)*N10)*N11) -> 18474.018 | O7: =(((O8*O9)*O10)*O11) -> 18515.35 | ... AQ7: =(((AQ8*AQ9)*AQ10)*AQ11) -> 19710.949
G8: National Live Births Per Month | H8: =national_live_births_per_month*(1+national_live_births_per_month_growth)^((COLUMN()-8)/12) -> 145833 | I8: =national_live_births_per_month*(1+national_live_births_per_month_growth)^((COLUMN()-8)/12) -> 146049.97 | J8: =national_live_births_per_month*(1+national_live_births_per_month_growth)^((COLUMN()-8)/12) -> 146267.25 | K8: =national_live_births_per_month*(1+national_live_births_per_month_growth)^((COLUMN()-8)/12) -> 146484.86 | L8: =national_live_births_per_month*(1+national_live_births_per_month_growth)^((COLUMN()-8)/12) -> 146702.8 | M8: =national_live_births_per_month*(1+national_live_births_per_month_growth)^((COLUMN()-8)/12) -> 146921.06 | N8: =national_live_births_per_month*(1+national_live_births_per_month_growth)^((COLUMN()-8)/12) -> 147139.64 | O8: =national_live_births_per_month*(1+national_live_births_per_month_growth)^((COLUMN()-8)/12) -> 147358.55 | ... AQ8: =national_live_births_per_month*(1+national_live_births_per_month_growth)^((COLUMN()-8)/12) -> 153622.03
G9: times Central Regional Opportunity Weight | H9: =central_regional_opportunity_weight*(1+central_regional_opportunity_weight_growth)^((COLUMN()-8)/12) -> 0.28 | I9: =central_regional_opportunity_weight*(1+central_regional_opportunity_weight_growth)^((COLUMN()-8)/12) -> 0.28 | J9: =central_regional_opportunity_weight*(1+central_regional_opportunity_weight_growth)^((COLUMN()-8)/12) -> 0.28 | K9: =central_regional_opportunity_weight*(1+central_regional_opportunity_weight_growth)^((COLUMN()-8)/12) -> 0.28 | L9: =central_regional_opportunity_weight*(1+central_regional_opportunity_weight_growth)^((COLUMN()-8)/12) -> 0.28 | M9: =central_regional_opportunity_weight*(1+central_regional_opportunity_weight_growth)^((COLUMN()-8)/12) -> 0.28 | N9: =central_regional_opportunity_weight*(1+central_regional_opportunity_weight_growth)^((COLUMN()-8)/12) -> 0.28 | O9: =central_regional_opportunity_weight*(1+central_regional_opportunity_weight_growth)^((COLUMN()-8)/12) -> 0.28 | ... AQ9: =central_regional_opportunity_weight*(1+central_regional_opportunity_weight_growth)^((COLUMN()-8)/12) -> 0.28
G10: times Central ANC Access Rate | H10: =central_anc_access_rate*(1+central_anc_access_rate_growth)^((COLUMN()-8)/12) -> 0.72 | I10: =central_anc_access_rate*(1+central_anc_access_rate_growth)^((COLUMN()-8)/12) -> 0.72017975 | J10: =central_anc_access_rate*(1+central_anc_access_rate_growth)^((COLUMN()-8)/12) -> 0.72035955 | K10: =central_anc_access_rate*(1+central_anc_access_rate_growth)^((COLUMN()-8)/12) -> 0.72053939 | L10: =central_anc_access_rate*(1+central_anc_access_rate_growth)^((COLUMN()-8)/12) -> 0.72071928 | M10: =central_anc_access_rate*(1+central_anc_access_rate_growth)^((COLUMN()-8)/12) -> 0.72089921 | N10: =central_anc_access_rate*(1+central_anc_access_rate_growth)^((COLUMN()-8)/12) -> 0.72107919 | O10: =central_anc_access_rate*(1+central_anc_access_rate_growth)^((COLUMN()-8)/12) -> 0.72125921 | ... AQ10: =central_anc_access_rate*(1+central_anc_access_rate_growth)^((COLUMN()-8)/12) -> 0.72631813
G11: times Central Third Trimester Window Rate | H11: =central_third_trimester_window_rate*(1+central_third_trimester_window_rate_growth)^((COLUMN()-8)/12) -> 0.62 | I11: =central_third_trimester_window_rate*(1+central_third_trimester_window_rate_growth)^((COLUMN()-8)/12) -> 0.62030915 | J11: =central_third_trimester_window_rate*(1+central_third_trimester_window_rate_growth)^((COLUMN()-8)/12) -> 0.62061846 | K11: =central_third_trimester_window_rate*(1+central_third_trimester_window_rate_growth)^((COLUMN()-8)/12) -> 0.62092791 | L11: =central_third_trimester_window_rate*(1+central_third_trimester_window_rate_growth)^((COLUMN()-8)/12) -> 0.62123753 | M11: =central_third_trimester_window_rate*(1+central_third_trimester_window_rate_growth)^((COLUMN()-8)/12) -> 0.6215473 | N11: =central_third_trimester_window_rate*(1+central_third_trimester_window_rate_growth)^((COLUMN()-8)/12) -> 0.62185722 | O11: =central_third_trimester_window_rate*(1+central_third_trimester_window_rate_growth)^((COLUMN()-8)/12) -> 0.6221673 | ... AQ11: =central_third_trimester_window_rate*(1+central_third_trimester_window_rate_growth)^((COLUMN()-8)/12) -> 0.6309125
F12: times Central Public Eligibility Rate | H12: =central_public_eligibility_rate*(1+central_public_eligibility_rate_growth)^((COLUMN()-8)/12) -> 0.28 | I12: =central_public_eligibility_rate*(1+central_public_eligibility_rate_growth)^((COLUMN()-8)/12) -> 0.28180153 | J12: =central_public_eligibility_rate*(1+central_public_eligibility_rate_growth)^((COLUMN()-8)/12) -> 0.28361465 | K12: =central_public_eligibility_rate*(1+central_public_eligibility_rate_growth)^((COLUMN()-8)/12) -> 0.28543943 | L12: =central_public_eligibility_rate*(1+central_public_eligibility_rate_growth)^((COLUMN()-8)/12) -> 0.28727596 | M12: =central_public_eligibility_rate*(1+central_public_eligibility_rate_growth)^((COLUMN()-8)/12) -> 0.2891243 | N12: =central_public_eligibility_rate*(1+central_public_eligibility_rate_growth)^((COLUMN()-8)/12) -> 0.29098454 | O12: =central_public_eligibility_rate*(1+central_public_eligibility_rate_growth)^((COLUMN()-8)/12) -> 0.29285674 | ... AQ12: =central_public_eligibility_rate*(1+central_public_eligibility_rate_growth)^((COLUMN()-8)/12) -> 0.35046446
F13: times Central Public Provider Recommendation Rate | H13: =central_public_provider_recommendation_rate*(1+central_public_provider_recommendation_rate_growth)^((COLUMN()-8)/12) -> 0.56 | I13: =central_public_provider_recommendation_rate*(1+central_public_provider_recommendation_rate_growth)^((COLUMN()-8)/12) -> 0.56183329 | J13: =central_public_provider_recommendation_rate*(1+central_public_provider_recommendation_rate_growth)^((COLUMN()-8)/12) -> 0.56367259 | K13: =central_public_provider_recommendation_rate*(1+central_public_provider_recommendation_rate_growth)^((COLUMN()-8)/12) -> 0.56551791 | L13: =central_public_provider_recommendation_rate*(1+central_public_provider_recommendation_rate_growth)^((COLUMN()-8)/12) -> 0.56736927 | M13: =central_public_provider_recommendation_rate*(1+central_public_provider_recommendation_rate_growth)^((COLUMN()-8)/12) -> 0.56922669 | N13: =central_public_provider_recommendation_rate*(1+central_public_provider_recommendation_rate_growth)^((COLUMN()-8)/12) -> 0.57109019 | O13: =central_public_provider_recommendation_rate*(1+central_public_provider_recommendation_rate_growth)^((COLUMN()-8)/12) -> 0.57295979 | ... AQ13: =central_public_provider_recommendation_rate*(1+central_public_provider_recommendation_rate_growth)^((COLUMN()-8)/12) -> 0.62786836
F14: times Central Public Acceptance Rate | H14: =central_public_acceptance_rate*(1+central_public_acceptance_rate_growth)^((COLUMN()-8)/12) -> 0.78 | I14: =central_public_acceptance_rate*(1+central_public_acceptance_rate_growth)^((COLUMN()-8)/12) -> 0.78128823 | J14: =central_public_acceptance_rate*(1+central_public_acceptance_rate_growth)^((COLUMN()-8)/12) -> 0.78257859 | K14: =central_public_acceptance_rate*(1+central_public_acceptance_rate_growth)^((COLUMN()-8)/12) -> 0.78387109 | L14: =central_public_acceptance_rate*(1+central_public_acceptance_rate_growth)^((COLUMN()-8)/12) -> 0.78516571 | M14: =central_public_acceptance_rate*(1+central_public_acceptance_rate_growth)^((COLUMN()-8)/12) -> 0.78646248 | N14: =central_public_acceptance_rate*(1+central_public_acceptance_rate_growth)^((COLUMN()-8)/12) -> 0.78776139 | O14: =central_public_acceptance_rate*(1+central_public_acceptance_rate_growth)^((COLUMN()-8)/12) -> 0.78906244 | ... AQ14: =central_public_acceptance_rate*(1+central_public_acceptance_rate_growth)^((COLUMN()-8)/12) -> 0.82637741
F15: times Central Public Stock Availability Rate | H15: =central_public_stock_availability_rate*(1+central_public_stock_availability_rate_growth)^((COLUMN()-8)/12) -> 0.9 | I15: =central_public_stock_availability_rate*(1+central_public_stock_availability_rate_growth)^((COLUMN()-8)/12) -> 0.90111734 | J15: =central_public_stock_availability_rate*(1+central_public_stock_availability_rate_growth)^((COLUMN()-8)/12) -> 0.90223607 | K15: =central_public_stock_availability_rate*(1+central_public_stock_availability_rate_growth)^((COLUMN()-8)/12) -> 0.90335618 | L15: =central_public_stock_availability_rate*(1+central_public_stock_availability_rate_growth)^((COLUMN()-8)/12) -> 0.90447769 | M15: =central_public_stock_availability_rate*(1+central_public_stock_availability_rate_growth)^((COLUMN()-8)/12) -> 0.90560058 | N15: =central_public_stock_availability_rate*(1+central_public_stock_availability_rate_growth)^((COLUMN()-8)/12) -> 0.90672488 | O15: =central_public_stock_availability_rate*(1+central_public_stock_availability_rate_growth)^((COLUMN()-8)/12) -> 0.90785056 | ... AQ15: =central_public_stock_availability_rate*(1+central_public_stock_availability_rate_growth)^((COLUMN()-8)/12) -> 0.93994361
F16: times Central Public Active Coverage State | H16: =0.08 -> 0.08 | I16: =H16+I17-I18 -> 0.10106166 | J16: =I16+J17-J18 -> 0.12218512 | K16: =J16+K17-K18 -> 0.14337055 | L16: =K16+L17-L18 -> 0.16461809 | M16: =L16+M17-M18 -> 0.1859279 | N16: =M16+N17-N18 -> 0.20730013 | O16: =N16+O17-O18 -> 0.22873493 | P16: =O16+P17-P18 -> 0.25023246 | ... AQ16: =AP16+AQ17-AQ18 -> 0.85495192
G17: Central Public Coverage Additions | H17: =central_public_coverage_additions*(1+central_public_coverage_additions_growth)^((COLUMN()-8)/12) -> 0.025 | I17: =central_public_coverage_additions*(1+central_public_coverage_additions_growth)^((COLUMN()-8)/12) -> 0.025061657 | J17: =central_public_coverage_additions*(1+central_public_coverage_additions_growth)^((COLUMN()-8)/12) -> 0.025123466 | K17: =central_public_coverage_additions*(1+central_public_coverage_additions_growth)^((COLUMN()-8)/12) -> 0.025185427 | L17: =central_public_coverage_additions*(1+central_public_coverage_additions_growth)^((COLUMN()-8)/12) -> 0.025247541 | M17: =central_public_coverage_additions*(1+central_public_coverage_additions_growth)^((COLUMN()-8)/12) -> 0.025309808 | N17: =central_public_coverage_additions*(1+central_public_coverage_additions_growth)^((COLUMN()-8)/12) -> 0.025372229 | O17: =central_public_coverage_additions*(1+central_public_coverage_additions_growth)^((COLUMN()-8)/12) -> 0.025434804 | ... AQ17: =central_public_coverage_additions*(1+central_public_coverage_additions_growth)^((COLUMN()-8)/12) -> 0.027250967
G18: plus Central Public Coverage Churn | H18: =central_public_coverage_churn*(1+central_public_coverage_churn_growth)^((COLUMN()-8)/12) -> 0.004 | I18: =central_public_coverage_churn*(1+central_public_coverage_churn_growth)^((COLUMN()-8)/12) -> 0.004 | J18: =central_public_coverage_churn*(1+central_public_coverage_churn_growth)^((COLUMN()-8)/12) -> 0.004 | K18: =central_public_coverage_churn*(1+central_public_coverage_churn_growth)^((COLUMN()-8)/12) -> 0.004 | L18: =central_public_coverage_churn*(1+central_public_coverage_churn_growth)^((COLUMN()-8)/12) -> 0.004 | M18: =central_public_coverage_churn*(1+central_public_coverage_churn_growth)^((COLUMN()-8)/12) -> 0.004 | N18: =central_public_coverage_churn*(1+central_public_coverage_churn_growth)^((COLUMN()-8)/12) -> 0.004 | O18: =central_public_coverage_churn*(1+central_public_coverage_churn_growth)^((COLUMN()-8)/12) -> 0.004 | ... AQ18: =central_public_coverage_churn*(1+central_public_coverage_churn_growth)^((COLUMN()-8)/12) -> 0.004
