Workbook

Sheet Monthly Headcount
B1: Group Headcount Report 2025
C2: Group | E2: Uganda | G2: APDL | I2: Tanzania | K2: Rwanda | M2: Burundi | O2: Kenya
C3: Number | D3: % | E3: Number | F3: % | G3: Number | H3: % | I3: Number | J3: % | K3: Number | L3: % | M3: Number | N3: % | O3: Number | P3: %
B4: Headcount December FY24 | C4: =SUM(E4,G4,I4,K4,M4,O4) -> 1173 | E4: 601 | G4: 219 | I4: 223 | K4: 36 | M4: 59 | O4: 35
A5: Monthly Headcount Growth (Direct staff) | C5: =SUM(E5,G5,I5,K5,M5,O5) -> 23 | D5: =C5/C4 -> 0.019607843 | E5: =E8-E4 -> 11 | F5: =E5/E4 -> 0.018302829 | G5: =G8-G4 -> 7 | H5: =G5/G4 -> 0.03196347 | I5: =I8-I4 -> 0 | J5: =I5/I4 -> 0 | K5: =K8-K4 -> 4 | L5: =K5/K4 -> 0.11111111 | M5: =M8-M4 -> 2 | N5: =M5/M4 -> 0.033898305 | O5: =O8-O4 -> -1 | P5: =O5/O4 -> -0.028571429
A7: 45658 | B7: Overall Headcount | C7: =SUM(E7,G7,I7,K7,M7,O7) -> 2151 | D7: =SUM(F7,H7,J7,L7,N7,P7) -> 1 | E7: =SUM(E8,E30,E33) -> 1004 | F7: =E7/C$7 -> 0.46675965 | G7: =SUM(G8,G30,G33) -> 716 | H7: =G7/C$7 -> 0.33286843 | I7: =SUM(I8,I30,I33) -> 243 | J7: =I7/C$7 -> 0.11297071 | K7: =SUM(K8,K30,K33) -> 77 | L7: =K7/C$7 -> 0.035797304 | M7: =SUM(M8,M30,M33) -> 67 | N7: =M7/C$7 -> 0.031148303 | O7: =SUM(O8,O30,O33) -> 44 | P7: =O7/C$7 -> 0.020455602
B8: Direct Staff | C8: =SUM(E8,G8,I8,K8,M8,O8) -> 1196 | D8: =C8/C7 -> 0.55602046 | E8: =E9+E10 -> 612 | F8: =E8/C8 -> 0.51170569 | G8: =G9+G10 -> 226 | H8: =G8/C8 -> 0.18896321 | I8: =I9+I10 -> 223 | J8: =I8/C8 -> 0.18645485 | K8: =K9+K10 -> 40 | L8: =K8/C8 -> 0.033444816 | M8: =M9+M10 -> 61 | N8: =M8/C8 -> 0.051003344 | O8: =O9+O10 -> 34 | P8: =O8/C8 -> 0.028428094
B9: Female | C9: =SUM(E9,G9,I9,K9,M9,O9) -> 307 | D9: =C9/C8 -> 0.25668896 | E9: 146 | F9: =E9/E8 -> 0.23856209 | G9: 45 | H9: =G9/G8 -> 0.19911504 | I9: 66 | J9: =I9/I8 -> 0.29596413 | K9: 15 | L9: =K9/K8 -> 0.375 | M9: 18 | N9: =M9/M8 -> 0.29508197 | O9: 17 | P9: =O9/O8 -> 0.5
B10: Male | C10: =SUM(E10,G10,I10,K10,M10,O10) -> 889 | D10: =C10/C8 -> 0.74331104 | E10: 466 | F10: =E11/E8 -> 0.86437908 | G10: 181 | H10: =G10/G8 -> 0.80088496 | I10: 157 | J10: =I10/I8 -> 0.70403587 | K10: 25 | L10: =K10/K8 -> 0.625 | M10: 43 | N10: =M10/M8 -> 0.70491803 | O10: 17 | P10: =O10/O8 -> 0.5
B11: Nationals | C11: =SUM(E11,G11,I11,K11,M11,O11) -> 1077 | D11: =C11/C8 -> 0.90050167 | E11: 529 | F11: =E11/E8 -> 0.86437908 | G11: 214 | H11: =G11/G8 -> 0.94690265 | I11: 209 | J11: =I11/I8 -> 0.93721973 | K11: 36 | L11: =K11/K8 -> 0.9 | M11: 56 | N11: =M11/M8 -> 0.91803279 | O11: 33 | P11: =O11/O8 -> 0.97058824
B12: Expatriates | C12: =SUM(E12,G12,I12,K12,M12,O12) -> 119 | D12: =C12/C8 -> 0.099498328 | E12: 83 | F12: =E12/E8 -> 0.13562092 | G12: 12 | H12: =G12/G8 -> 0.053097345 | I12: 14 | J12: =I12/I8 -> 0.062780269 | K12: 4 | L12: =K12/K8 -> 0.1 | M12: 5 | N12: =M12/M8 -> 0.081967213 | O12: 1 | P12: =O12/O8 -> 0.029411765
B13: Management | C13: =SUM(E13,G13,I13,K13,M13,O13) -> 267 | D13: =C13/C8 -> 0.22324415 | E13: 127 | F13: =E13/E8 -> 0.20751634 | G13: 65 | H13: =G13/G8 -> 0.28761062 | I13: 40 | J13: =I13/I8 -> 0.1793722 | K13: 11 | L13: =K13/K8 -> 0.275 | M13: 17 | N13: =M13/M8 -> 0.27868852 | O13: 7 | P13: =O13/O8 -> 0.20588235
B14: Female in Management | C14: =SUM(E14,G14,I14,K14,M14,O14) -> 45 | D14: =C14/C13 -> 0.16853933 | E14: 18 | F14: =E14/E13 -> 0.14173228 | G14: 10 | H14: =G14/G13 -> 0.15384615 | I14: 8 | J14: =I14/I13 -> 0.2 | K14: 3 | L14: =K14/K13 -> 0.27272727 | M14: 4 | N14: =M14/M13 -> 0.23529412 | O14: 2 | P14: =O14/O13 -> 0.28571429
B15: Below 40 years of age | C15: =SUM(E15,G15,I15,K15,M15,O15) -> 948 | D15: =C15/C8 -> 0.79264214 | E15: 469 | F15: =E15/E8 -> 0.76633987 | G15: 187 | H15: =G15/G8 -> 0.82743363 | I15: 182 | J15: =I15/I8 -> 0.8161435 | K15: 34 | L15: =K15/K8 -> 0.85 | M15: 50 | N15: =M15/M8 -> 0.81967213 | O15: 26 | P15: =O15/O8 -> 0.76470588
B16: Atleast 40 years of age | C16: =SUM(E16,G16,I16,K16,M16,O16) -> 248 | D16: =C16/C8 -> 0.20735786 | E16: 143 | F16: =E16/E8 -> 0.23366013 | G16: 39 | H16: =G16/G8 -> 0.17256637 | I16: 41 | J16: =I16/I8 -> 0.1838565 | K16: 6 | L16: =K16/K8 -> 0.15 | M16: 11 | N16: =M16/M8 -> 0.18032787 | O16: 8 | P16: =O16/O8 -> 0.23529412
B17: Less than 5 years with Abacus | C17: =SUM(E17,G17,I17,K17,M17,O17) -> 678 | D17: =C17/C8 -> 0.56688963 | E17: 361 | F17: =E17/E8 -> 0.58986928 | G17: 91 | H17: =G17/G8 -> 0.40265487 | I17: 140 | J17: =I17/I8 -> 0.62780269 | K17: 30 | L17: =K17/K8 -> 0.75 | M17: 31 | N17: =M17/M8 -> 0.50819672 | O17: 25 | P17: =O17/O8 -> 0.73529412
B18: Atleast 5 years with Abacus | C18: =SUM(E18,G18,I18,K18,M18,O18) -> 518 | D18: =C18/C8 -> 0.43311037 | E18: 251 | F18: =E18/E8 -> 0.41013072 | G18: 135 | H18: =G18/G8 -> 0.59734513 | I18: 83 | J18: =I18/I8 -> 0.37219731 | K18: 10 | L18: =K18/K8 -> 0.25 | M18: =M8-M17 -> 30 | N18: =M18/M8 -> 0.49180328 | O18: 9 | P18: =O18/O8 -> 0.26470588
B19: Total New hires | C19: =SUM(E19,G19,I19,K19,M19,O19) -> 27 | D19: =SUM(D20:D22) -> 1 | E19: =SUM(E20:E22) -> 4 | F19: =SUM(F20:F22) -> 1 | G19: =SUM(G20:G22) -> 3 | H19: =SUM(H20:H22) -> 1 | I19: =SUM(I20:I22) -> 14 | J19: =SUM(J20:J22) -> 1 | K19: =SUM(K20:K22) -> 1 | ... P19: =SUM(P20:P22) -> 1
B20: New hires at EXCO | C20: =SUM(E20,G20,I20,K20,M20,O20) -> 0 | D20: =C20/C19 -> 0 | E20: 0 | F20: =E20/E19 -> 0 | G20: 0 | H20: 0 | I20: 0 | J20: 0 | K20: 0 | L20: 0 | M20: 0 | N20: 0 | O20: 0 | P20: 0
B21: New hires at EXCO - 1&2 | C21: =SUM(E21,G21,I21,K21,M21,O21) -> 1 | D21: =C21/C19 -> 0.037037037 | E21: 0 | F21: =E21/E19 -> 0 | G21: 0 | H21: =G21/G19 -> 0 | I21: 0 | J21: =I21/I19 -> 0 | K21: 1 | L21: - | M21: 0 | N21: =M21/M19 -> 0 | O21: 0 | P21: =O21/O19 -> 0
B22: New hires at Other Levels | C22: =SUM(E22,G22,I22,K22,M22,O22) -> 26 | D22: =C22/C19 -> 0.96296296 | E22: 4 | F22: =E22/E19 -> 1 | G22: 3 | H22: =G22/G19 -> 1 | I22: 14 | J22: =I22/I19 -> 1 | K22: 0 | L22: =K22/K19 -> 0 | M22: 1 | N22: =M22/M19 -> 1 | O22: 4 | P22: =O22/O19 -> 1
B23: Total Exits | C23: =SUM(E23,G23,I23,K23,M23,O23) -> 14 | D23: =SUM(D24:D26) -> 0.011705686 | E23: =SUM(E24:E26) -> 6 | F23: =SUM(F24:F26) -> 0.0098039216 | G23: =SUM(G24:G26) -> 1 | H23: =SUM(H24:H26) -> 0.0044247788 | I23: =SUM(I24:I26) -> 4 | J23: =SUM(J24:J26) -> 0.01793722 | K23: =SUM(K24:K26) -> 1 | ... P23: =SUM(P24:P26) -> 0.029411765
B24: Exits at EXCO | C24: =SUM(E24,G24,I24,K24,M24,O24) -> 0 | D24: =C24/$C$8 -> 0 | E24: 0 | F24: =E24/$E$8 -> 0 | G24: 0 | H24: =G24/$G$8 -> 0 | I24: 0 | J24: =I24/$I$8 -> 0 | K24: 0 | L24: =K24/$K$8 -> 0 | M24: 0 | N24: =M24/$M$8 -> 0 | O24: 0 | P24: =O24/$O$8 -> 0
B25: Exits at EXCO - 1&2 | C25: =SUM(E25,G25,I25,K25,M25,O25) -> 1 | D25: =C25/$C$8 -> 0.0008361204 | E25: 1 | F25: =E25/$E$8 -> 0.0016339869 | G25: 0 | H25: =G25/$G$8 -> 0 | I25: 0 | J25: =I25/$I$8 -> 0 | K25: 0 | L25: =K25/$K$8 -> 0 | M25: 0 | N25: =M25/$M$8 -> 0 | O25: 0 | P25: =O25/$O$8 -> 0
B26: Exits at Other Levels | C26: =SUM(E26,G26,I26,K26,M26,O26) -> 13 | D26: =C26/$C$8 -> 0.010869565 | E26: 5 | F26: =E26/$E$8 -> 0.0081699346 | G26: 1 | H26: =G26/$G$8 -> 0.0044247788 | I26: 4 | J26: =I26/$I$8 -> 0.01793722 | K26: 1 | L26: =K26/$K$8 -> 0.025 | M26: 1 | N26: =M26/$M$8 -> 0.016393443 | O26: 1 | P26: =O26/$O$8 -> 0.029411765
B27: Total Internal Movements | C27: =SUM(E27,G27,I27,K27,M27,O27) -> 29 | E27: =SUM(E28:E29) -> 16 | F27: =SUM(F28:F29) -> 0 | G27: =SUM(G28:G29) -> 1 | H27: =SUM(H28:H29) -> 0 | I27: =SUM(I28:I29) -> 7 | J27: =SUM(J28:J29) -> 0 | K27: =SUM(K28:K29) -> 0 | L27: =SUM(L28:L29) -> 0 | ... P27: =SUM(P28:P29) -> 0
B28: Promotions | C28: =SUM(E28,G28,I28,K28,M28,O28) -> 28 | E28: 15 | G28: 1 | I28: 7 | K28: 0 | M28: 3 | O28: 2
B29: Transfers | C29: =SUM(E29,G29,I29,K29,M29,O29) -> 1 | E29: 1 | G29: 0 | I29: 0 | K29: 0 | M29: 0 | O29: 0
B30: Principals | C30: =SUM(E30,G30,I30,K30,M30,O30) -> 413 | D30: =C30/C7 -> 0.19200372 | E30: =E31+E32 -> 340 | F30: =E30/C30 -> 0.82324455 | G30: =G31+G32 -> 0 | H30: =G30/C30 -> 0 | I30: =I31+I32 -> 20 | J30: =I30/C30 -> 0.04842615 | K30: =K31+K32 -> 37 | L30: =K30/E30 -> 0.10882353 | M30: =M31+M32 -> 6 | N30: =M30/C30 -> 0.014527845 | O30: =O31+O32 -> 10 | P30: =O30/C30 -> 0.024213075
B31: Female | C31: =SUM(E31,G31,I31,K31,M31,O31) -> 122 | D31: =C31/C30 -> 0.29539952 | E31: 97 | F31: =E31/E30 -> 0.28529412 | G31: 0 | H31: 0 | I31: 6 | J31: =I31/I30 -> 0.3 | K31: 15 | L31: =K31/K30 -> 0.40540541 | M31: 1 | N31: =M31/M30 -> 0.16666667 | O31: 3 | P31: 0
B32: Male | C32: =SUM(E32,G32,I32,K32,M32,O32) -> 291 | D32: =C32/C30 -> 0.70460048 | E32: 243 | F32: =E32/E30 -> 0.71470588 | G32: 0 | H32: 0 | I32: 14 | J32: =I32/I30 -> 0.7 | K32: 22 | L32: =K32/K30 -> 0.59459459 | M32: 5 | N32: =M32/M30 -> 0.83333333 | O32: 7 | P32: 0
B33: Casuals/Contractors | C33: =SUM(E33,G33,I33,K33,M33,O33) -> 542 | D33: =C33/C7 -> 0.25197583 | E33: =E34+E35 -> 52 | F33: =E33/C33 -> 0.095940959 | G33: =G34+G35 -> 490 | H33: =G33/C33 -> 0.90405904 | I33: =I34+I35 -> 0 | J33: 0 | K33: =K34+K35 -> 0 | L33: =K33/C33 -> 0 | M33: =M34+M35 -> 0 | N33: 0 | O33: =O34+O35 -> 0 | P33: 0
B34: Female | C34: =SUM(E34,G34,I34,K34,M34,O34) -> 258 | D34: =C34/C33 -> 0.47601476 | E34: 6 | F34: =E34/E33 -> 0.11538462 | G34: 252 | H34: =G34/G33 -> 0.51428571 | I34: 0 | J34: 0 | K34: 0 | L34: 0 | M34: 0 | N34: 0 | O34: 0 | P34: 0
B35: Male | C35: =SUM(E35,G35,I35,K35,M35,O35) -> 284 | D35: =C35/C33 -> 0.52398524 | E35: 46 | F35: =E35/E33 -> 0.88461538 | G35: 238 | H35: =G35/G33 -> 0.48571429 | I35: 0 | J35: 0 | K35: 0 | L35: 0 | M35: 0 | N35: 0 | O35: 0 | P35: 0
A37: Monthly Headcount Growth (Direct staff) | C37: =C39-C8 -> 12 | D37: =C37/C8 -> 0.010033445 | E37: =E39-E8 -> 9 | F37: =E37/E8 -> 0.014705882 | G37: =G39-G8 -> 1 | H37: =G37/G8 -> 0.0044247788 | I37: =I39-I8 -> 3 | J37: =I37/I8 -> 0.013452915 | K37: =K39-K8 -> 0 | L37: =K37/K8 -> 0 | M37: =M39-M8 -> -1 | N37: =M37/M8 -> -0.016393443 | O37: =O39-O8 -> 0 | P37: =O37/O8 -> 0
A38: 45689 | B38: Overall Headcount | C38: =SUM(E38,G38,I38,K38,M38,O38) -> 2133 | D38: =SUM(F38,H38,J38,L38,N38,P38) -> 0.9998313 | E38: =SUM(E39,E61,E64) -> 997 | F38: =E38/C38 -> 0.46741678 | G38: =SUM(G39,G61,G64) -> 703 | H38: =G38/C38 -> 0.32958275 | I38: =SUM(I39,I61,I64) -> 248 | J38: =I38/C38 -> 0.11626817 | K38: =SUM(K39,K61,K64) -> 76 | L38: =K38/C38 -> 0.035630567 | M38: =SUM(M39,M61,M64) -> 66 | N38: =M38/C38 -> 0.030942335 | O38: =SUM(O39,O61,O64) -> 43 | P38: =O38/C$7 -> 0.019990702
B39: Direct Staff | C39: =SUM(E39,G39,I39,K39,M39,O39) -> 1208 | D39: =C39/C38 -> 0.56633849 | E39: =E40+E41 -> 621 | F39: =E39/E38 -> 0.62286861 | G39: =G40+G41 -> 227 | H39: =G39/C39 -> 0.18791391 | I39: =I40+I41 -> 226 | J39: =I39/C39 -> 0.18708609 | K39: =K40+K41 -> 40 | L39: =K39/C39 -> 0.033112583 | M39: =M40+M41 -> 60 | N39: =M39/C39 -> 0.049668874 | O39: =O40+O41 -> 34 | P39: =O39/C39 -> 0.028145695
B40: Female | C40: =SUM(E40,G40,I40,K40,M40,O40) -> 310 | D40: =C40/C39 -> 0.25662252 | E40: 147 | F40: =E40/$E$39 -> 0.23671498 | G40: 45 | H40: =G40/G39 -> 0.19823789 | I40: 68 | J40: =I40/I39 -> 0.30088496 | K40: 14 | L40: =K40/K39 -> 0.35 | M40: 18 | N40: =M40/M39 -> 0.3 | O40: 18 | P40: =O40/O39 -> 0.52941176
B41: Male | C41: =SUM(E41,G41,I41,K41,M41,O41) -> 898 | D41: =C41/C39 -> 0.74337748 | E41: 474 | F41: =E41/$E$39 -> 0.76328502 | G41: 182 | H41: =G41/G39 -> 0.80176211 | I41: 158 | J41: =I41/I39 -> 0.69911504 | K41: 26 | L41: =K41/K39 -> 0.65 | M41: 42 | N41: =M41/M39 -> 0.7 | O41: 16 | P41: =O41/O39 -> 0.47058824
B42: Nationals | C42: =SUM(E42,G42,I42,K42,M42,O42) -> 1085 | D42: =C42/C39 -> 0.89817881 | E42: 536 | F42: =E42/$E$39 -> 0.86312399 | G42: 215 | H42: =G42/G39 -> 0.94713656 | I42: 211 | J42: =I42/I39 -> 0.93362832 | K42: 35 | L42: =K42/K39 -> 0.875 | M42: 55 | N42: =M42/M39 -> 0.91666667 | O42: 33 | P42: =O42/O39 -> 0.97058824
...

Sheet YTD Headcount
B1: Group YTD Headcount Report FY25
C2: Group | E2: Uganda | G2: APDL | I2: Tanzania | K2: Rwanda | M2: Burundi | O2: Kenya
C3: Number | D3: % | E3: Number | F3: % | G3: Number | H3: % | I3: Number | J3: % | K3: Number | L3: % | M3: Number | N3: % | O3: Number | P3: %
A5: Q1 | B5: Overall Headcount | C5: =SUM(E5,G5,I5,K5,M5,O5) -> 2149.6667 | D5: =SUM(F5,H5,J5,L5,N5,P5) -> 1 | E5: =SUM(E6,E28,E31) -> 996.66667 | F5: =E5/C$5 -> 0.46363777 | G5: =SUM(G6,G28,G31) -> 720.33333 | H5: =G5/C$5 -> 0.33509071 | I5: =SUM(I6,I28,I31) -> 248 | J5: =I5/C$5 -> 0.11536672 | K5: =SUM(K6,K28,K31) -> 76 | L5: =K5/C$5 -> 0.035354318 | M5: =SUM(M6,M28,M31) -> 65.666667 | N5: =M5/C$5 -> 0.030547372 | O5: =SUM(O6,O28,O31) -> 43 | P5: =O5/C$5 -> 0.020003101
B6: Direct Staff | C6: =SUM(E6,G6,I6,K6,M6,O6) -> 1202 | D6: =C6/C5 -> 0.55915646 | E6: =E7+E8 -> 616.66667 | F6: =E6/C6 -> 0.51303383 | G6: =G7+G8 -> 226.33333 | H6: =G6/C6 -> 0.18829728 | I6: =I7+I8 -> 226.33333 | J6: =I6/C6 -> 0.18829728 | K6: =K7+K8 -> 39.333333 | L6: =K6/C6 -> 0.032723239 | M6: =M7+M8 -> 59.666667 | N6: =M6/C6 -> 0.04963949 | O6: =O7+O8 -> 33.666667 | P6: =O6/C6 -> 0.028008874
B7: Female | C7: =SUM(E7,G7,I7,K7,M7,O7) -> 307.33333 | D7: =C7/C6 -> 0.25568497 | E7: =AVERAGE('Monthly Headcount'!E9,'Monthly Headcount'!E40,'Monthly Headcount'!E71) -> 146 | F7: =E7/E6 -> 0.23675676 | G7: =AVERAGE('Monthly Headcount'!G9,'Monthly Headcount'!G40,'Monthly Headcount'!G71) -> 45 | H7: =G7/G6 -> 0.1988218 | I7: =AVERAGE('Monthly Headcount'!I9,'Monthly Headcount'!I40,'Monthly Headcount'!I71) -> 67.333333 | J7: =I7/I6 -> 0.29749632 | K7: =AVERAGE('Monthly Headcount'!K9,'Monthly Headcount'!K40,'Monthly Headcount'!K71) -> 14 | L7: =K7/K6 -> 0.3559322 | M7: =AVERAGE('Monthly Headcount'!M9,'Monthly Headcount'!M40,'Monthly Headcount'!M71) -> 17.666667 | N7: =M7/M6 -> 0.29608939 | O7: =AVERAGE('Monthly Headcount'!O9,'Monthly Headcount'!O40,'Monthly Headcount'!O71) -> 17.333333 | P7: =O7/O6 -> 0.51485149
B8: Male | C8: =SUM(E8,G8,I8,K8,M8,O8) -> 894.66667 | D8: =C8/C6 -> 0.74431503 | E8: =AVERAGE('Monthly Headcount'!E10,'Monthly Headcount'!E41,'Monthly Headcount'!E72) -> 470.66667 | F8: =E9/E6 -> 0.86324324 | G8: =AVERAGE('Monthly Headcount'!G10,'Monthly Headcount'!G41,'Monthly Headcount'!G72) -> 181.33333 | H8: =G8/G6 -> 0.8011782 | I8: =AVERAGE('Monthly Headcount'!I10,'Monthly Headcount'!I41,'Monthly Headcount'!I72) -> 159 | J8: =I8/I6 -> 0.70250368 | K8: =AVERAGE('Monthly Headcount'!K10,'Monthly Headcount'!K41,'Monthly Headcount'!K72) -> 25.333333 | L8: =K8/K6 -> 0.6440678 | M8: =AVERAGE('Monthly Headcount'!M10,'Monthly Headcount'!M41,'Monthly Headcount'!M72) -> 42 | N8: =M8/M6 -> 0.70391061 | O8: =AVERAGE('Monthly Headcount'!O10,'Monthly Headcount'!O41,'Monthly Headcount'!O72) -> 16.333333 | P8: =O8/O6 -> 0.48514851
B9: Nationals | C9: =SUM(E9,G9,I9,K9,M9,O9) -> 1080.3333 | D9: =C9/C6 -> 0.89877981 | E9: =AVERAGE('Monthly Headcount'!E11,'Monthly Headcount'!E42,'Monthly Headcount'!E73) -> 532.33333 | F9: =E9/E6 -> 0.86324324 | G9: =AVERAGE('Monthly Headcount'!G11,'Monthly Headcount'!G42,'Monthly Headcount'!G73) -> 214.33333 | H9: =G9/G6 -> 0.94698085 | I9: =AVERAGE('Monthly Headcount'!I11,'Monthly Headcount'!I42,'Monthly Headcount'!I73) -> 211.33333 | J9: =I9/I6 -> 0.93372607 | K9: =AVERAGE('Monthly Headcount'!K11,'Monthly Headcount'!K42,'Monthly Headcount'!K73) -> 35 | L9: =K9/K6 -> 0.88983051 | M9: =AVERAGE('Monthly Headcount'!M11,'Monthly Headcount'!M42,'Monthly Headcount'!M73) -> 54.666667 | N9: =M9/M6 -> 0.91620112 | O9: =AVERAGE('Monthly Headcount'!O11,'Monthly Headcount'!O42,'Monthly Headcount'!O73) -> 32.666667 | P9: =O9/O6 -> 0.97029703
B10: Expatriates | C10: =SUM(E10,G10,I10,K10,M10,O10) -> 121.66667 | D10: =C10/C6 -> 0.10122019 | E10: =AVERAGE('Monthly Headcount'!E12,'Monthly Headcount'!E43,'Monthly Headcount'!E74) -> 84.333333 | F10: =E10/E6 -> 0.13675676 | G10: =AVERAGE('Monthly Headcount'!G12,'Monthly Headcount'!G43,'Monthly Headcount'!G74) -> 12 | H10: =G10/G6 -> 0.053019146 | I10: =AVERAGE('Monthly Headcount'!I12,'Monthly Headcount'!I43,'Monthly Headcount'!I74) -> 15 | J10: =I10/I6 -> 0.066273932 | K10: =AVERAGE('Monthly Headcount'!K12,'Monthly Headcount'!K43,'Monthly Headcount'!K74) -> 4.3333333 | L10: =K10/K6 -> 0.11016949 | M10: =AVERAGE('Monthly Headcount'!M12,'Monthly Headcount'!M43,'Monthly Headcount'!M74) -> 5 | N10: =M10/M6 -> 0.083798883 | O10: =AVERAGE('Monthly Headcount'!O12,'Monthly Headcount'!O43,'Monthly Headcount'!O74) -> 1 | P10: =O10/O6 -> 0.02970297
B11: Management | C11: =SUM(E11,G11,I11,K11,M11,O11) -> 266.33333 | D11: =C11/C6 -> 0.22157515 | E11: =AVERAGE('Monthly Headcount'!E13,'Monthly Headcount'!E44,'Monthly Headcount'!E75) -> 126.66667 | F11: =E11/E6 -> 0.20540541 | G11: =AVERAGE('Monthly Headcount'!G13,'Monthly Headcount'!G44,'Monthly Headcount'!G75) -> 64 | H11: =G11/G6 -> 0.28276878 | I11: =AVERAGE('Monthly Headcount'!I13,'Monthly Headcount'!I44,'Monthly Headcount'!I75) -> 41 | J11: =I11/I6 -> 0.18114875 | K11: =AVERAGE('Monthly Headcount'!K13,'Monthly Headcount'!K44,'Monthly Headcount'!K75) -> 11.333333 | L11: =K11/K6 -> 0.28813559 | M11: =AVERAGE('Monthly Headcount'!M13,'Monthly Headcount'!M44,'Monthly Headcount'!M75) -> 16.333333 | N11: =M11/M6 -> 0.27374302 | O11: =AVERAGE('Monthly Headcount'!O13,'Monthly Headcount'!O44,'Monthly Headcount'!O75) -> 7 | P11: =O11/O6 -> 0.20792079
B12: Female in Management | C12: =SUM(E12,G12,I12,K12,M12,O12) -> 44.666667 | D12: =C12/C11 -> 0.16770964 | E12: =AVERAGE('Monthly Headcount'!E14,'Monthly Headcount'!E45,'Monthly Headcount'!E76) -> 18.666667 | F12: =E12/E11 -> 0.14736842 | G12: =AVERAGE('Monthly Headcount'!G14,'Monthly Headcount'!G45,'Monthly Headcount'!G76) -> 9.3333333 | H12: =G12/G11 -> 0.14583333 | I12: =AVERAGE('Monthly Headcount'!I14,'Monthly Headcount'!I45,'Monthly Headcount'!I76) -> 8 | J12: =I12/I11 -> 0.19512195 | K12: =AVERAGE('Monthly Headcount'!K14,'Monthly Headcount'!K45,'Monthly Headcount'!K76) -> 2.6666667 | L12: =K12/K11 -> 0.23529412 | M12: =AVERAGE('Monthly Headcount'!M14,'Monthly Headcount'!M45,'Monthly Headcount'!M76) -> 4 | N12: =M12/M11 -> 0.24489796 | O12: =AVERAGE('Monthly Headcount'!O14,'Monthly Headcount'!O45,'Monthly Headcount'!O76) -> 2 | P12: =O12/O11 -> 0.28571429
B13: Below 40 years of age | C13: =SUM(E13,G13,I13,K13,M13,O13) -> 950.66667 | D13: =C13/C6 -> 0.79090405 | E13: =AVERAGE('Monthly Headcount'!E15,'Monthly Headcount'!E46,'Monthly Headcount'!E77) -> 473.66667 | F13: =E13/E6 -> 0.76810811 | G13: =AVERAGE('Monthly Headcount'!G15,'Monthly Headcount'!G46,'Monthly Headcount'!G77) -> 184.33333 | H13: =G13/G6 -> 0.81443299 | I13: =AVERAGE('Monthly Headcount'!I15,'Monthly Headcount'!I46,'Monthly Headcount'!I77) -> 184.33333 | J13: =I13/I6 -> 0.81443299 | K13: =AVERAGE('Monthly Headcount'!K15,'Monthly Headcount'!K46,'Monthly Headcount'!K77) -> 33.666667 | L13: =K13/K6 -> 0.8559322 | M13: =AVERAGE('Monthly Headcount'!M15,'Monthly Headcount'!M46,'Monthly Headcount'!M77) -> 48.666667 | N13: =M13/M6 -> 0.81564246 | O13: =AVERAGE('Monthly Headcount'!O15,'Monthly Headcount'!O46,'Monthly Headcount'!O77) -> 26 | P13: =O13/O6 -> 0.77227723
B14: Atleast 40 years of age | C14: =SUM(E14,G14,I14,K14,M14,O14) -> 251.33333 | D14: =C14/C6 -> 0.20909595 | E14: =AVERAGE('Monthly Headcount'!E16,'Monthly Headcount'!E47,'Monthly Headcount'!E78) -> 143 | F14: =E14/E6 -> 0.23189189 | G14: =AVERAGE('Monthly Headcount'!G16,'Monthly Headcount'!G47,'Monthly Headcount'!G78) -> 42 | H14: =G14/G6 -> 0.18556701 | I14: =AVERAGE('Monthly Headcount'!I16,'Monthly Headcount'!I47,'Monthly Headcount'!I78) -> 42 | J14: =I14/I6 -> 0.18556701 | K14: =AVERAGE('Monthly Headcount'!K16,'Monthly Headcount'!K47,'Monthly Headcount'!K78) -> 5.6666667 | L14: =K14/K6 -> 0.1440678 | M14: =AVERAGE('Monthly Headcount'!M16,'Monthly Headcount'!M47,'Monthly Headcount'!M78) -> 11 | N14: =M14/M6 -> 0.18435754 | O14: =AVERAGE('Monthly Headcount'!O16,'Monthly Headcount'!O47,'Monthly Headcount'!O78) -> 7.6666667 | P14: =O14/O6 -> 0.22772277
B15: Less than 5 years with Abacus | C15: =SUM(E15,G15,I15,K15,M15,O15) -> 685.66667 | D15: =C15/C6 -> 0.57043816 | E15: =AVERAGE('Monthly Headcount'!E17,'Monthly Headcount'!E48,'Monthly Headcount'!E79) -> 365.66667 | F15: =E15/E6 -> 0.59297297 | G15: =AVERAGE('Monthly Headcount'!G17,'Monthly Headcount'!G48,'Monthly Headcount'!G79) -> 92 | H15: =G15/G6 -> 0.40648012 | I15: =AVERAGE('Monthly Headcount'!I17,'Monthly Headcount'!I48,'Monthly Headcount'!I79) -> 143 | J15: =I15/I6 -> 0.63181149 | K15: =AVERAGE('Monthly Headcount'!K17,'Monthly Headcount'!K48,'Monthly Headcount'!K79) -> 29.333333 | L15: =K15/K6 -> 0.74576271 | M15: =AVERAGE('Monthly Headcount'!M17,'Monthly Headcount'!M48,'Monthly Headcount'!M79) -> 30.333333 | N15: =M15/M6 -> 0.50837989 | O15: =AVERAGE('Monthly Headcount'!O17,'Monthly Headcount'!O48,'Monthly Headcount'!O79) -> 25.333333 | P15: =O15/O6 -> 0.75247525
B16: Atleast 5 years with Abacus | C16: =SUM(E16,G16,I16,K16,M16,O16) -> 516.33333 | D16: =C16/C6 -> 0.42956184 | E16: =AVERAGE('Monthly Headcount'!E18,'Monthly Headcount'!E49,'Monthly Headcount'!E80) -> 251 | F16: =E16/E6 -> 0.40702703 | G16: =AVERAGE('Monthly Headcount'!G18,'Monthly Headcount'!G49,'Monthly Headcount'!G80) -> 134.33333 | H16: =G16/G6 -> 0.59351988 | I16: =AVERAGE('Monthly Headcount'!I18,'Monthly Headcount'!I49,'Monthly Headcount'!I80) -> 83.333333 | J16: =I16/I6 -> 0.36818851 | K16: =AVERAGE('Monthly Headcount'!K18,'Monthly Headcount'!K49,'Monthly Headcount'!K80) -> 10 | L16: =K16/K6 -> 0.25423729 | M16: =AVERAGE('Monthly Headcount'!M18,'Monthly Headcount'!M49,'Monthly Headcount'!M80) -> 29.333333 | N16: =M16/M6 -> 0.49162011 | O16: =AVERAGE('Monthly Headcount'!O18,'Monthly Headcount'!O49,'Monthly Headcount'!O80) -> 8.3333333 | P16: =O16/O6 -> 0.24752475
B17: Total New hires | C17: =SUM(E17,G17,I17,K17,M17,O17) -> 21.666667 | D17: =SUM(D18:D20) -> 0.018025513 | E17: =SUM(E18:E20) -> 6.6666667 | F17: =SUM(F18:F20) -> 1 | G17: =SUM(G18:G20) -> 2.3333333 | H17: =SUM(H18:H20) -> 1 | I17: =SUM(I18:I20) -> 9.6666667 | J17: =SUM(J18:J20) -> 1 | K17: =SUM(K18:K20) -> 0.66666667 | ... P17: =SUM(P18:P20) -> 1
B18: New hires at EXCO | C18: =SUM(E18,G18,I18,K18,M18,O18) -> 0.33333333 | D18: =C18/$C$6 -> 0.00027731559 | E18: =AVERAGE('Monthly Headcount'!E20,'Monthly Headcount'!E51,'Monthly Headcount'!E82) -> 0.33333333 | F18: =E18/E17 -> 0.05 | G18: =AVERAGE('Monthly Headcount'!G20,'Monthly Headcount'!G51,'Monthly Headcount'!G82) -> 0 | H18: 0 | I18: =AVERAGE('Monthly Headcount'!I20,'Monthly Headcount'!I51,'Monthly Headcount'!I82) -> 0 | J18: 0 | K18: =AVERAGE('Monthly Headcount'!K20,'Monthly Headcount'!K51,'Monthly Headcount'!K82) -> 0 | L18: 0 | M18: =AVERAGE('Monthly Headcount'!M20,'Monthly Headcount'!M51,'Monthly Headcount'!M82) -> 0 | N18: 0 | O18: =AVERAGE('Monthly Headcount'!O20,'Monthly Headcount'!O51,'Monthly Headcount'!O82) -> 0 | P18: 0
B19: New hires at EXCO - 1&2 | C19: =SUM(E19,G19,I19,K19,M19,O19) -> 1 | D19: =C19/$C$6 -> 0.00083194676 | E19: =AVERAGE('Monthly Headcount'!E21,'Monthly Headcount'!E52,'Monthly Headcount'!E83) -> 0 | F19: =E19/E17 -> 0 | G19: =AVERAGE('Monthly Headcount'!G21,'Monthly Headcount'!G52,'Monthly Headcount'!G83) -> 0 | H19: =G19/G17 -> 0 | I19: =AVERAGE('Monthly Headcount'!I21,'Monthly Headcount'!I52,'Monthly Headcount'!I83) -> 0.33333333 | J19: =I19/I17 -> 0.034482759 | K19: =AVERAGE('Monthly Headcount'!K21,'Monthly Headcount'!K52,'Monthly Headcount'!K83) -> 0.66666667 | L19: - | M19: =AVERAGE('Monthly Headcount'!M21,'Monthly Headcount'!M52,'Monthly Headcount'!M83) -> 0 | N19: =M19/M17 -> 0 | O19: =AVERAGE('Monthly Headcount'!O21,'Monthly Headcount'!O52,'Monthly Headcount'!O83) -> 0 | P19: =O19/O17 -> 0
B20: New hires at Other Levels | C20: =SUM(E20,G20,I20,K20,M20,O20) -> 20.333333 | D20: =C20/$C$6 -> 0.016916251 | E20: =AVERAGE('Monthly Headcount'!E22,'Monthly Headcount'!E53,'Monthly Headcount'!E84) -> 6.3333333 | F20: =E20/E17 -> 0.95 | G20: =AVERAGE('Monthly Headcount'!G22,'Monthly Headcount'!G53,'Monthly Headcount'!G84) -> 2.3333333 | H20: =G20/G17 -> 1 | I20: =AVERAGE('Monthly Headcount'!I22,'Monthly Headcount'!I53,'Monthly Headcount'!I84) -> 9.3333333 | J20: =I20/I17 -> 0.96551724 | K20: 0 | L20: =K20/K17 -> 0 | M20: =AVERAGE('Monthly Headcount'!M22,'Monthly Headcount'!M53,'Monthly Headcount'!M84) -> 0.33333333 | N20: =M20/M17 -> 1 | O20: =AVERAGE('Monthly Headcount'!O22,'Monthly Headcount'!O53,'Monthly Headcount'!O84) -> 2 | P20: =O20/O17 -> 1
B21: Total Exits | C21: =SUM(E21,G21,I21,K21,M21,O21) -> 26.666667 | D21: =SUM(D22:D24) -> 0.022185247 | E21: =SUM(E22:E24) -> 12 | F21: =SUM(F22:F24) -> 0.019459459 | G21: =SUM(G22:G24) -> 4 | H21: =SUM(H22:H24) -> 0.017673049 | I21: =SUM(I22:I24) -> 6.3333333 | J21: =SUM(J22:J24) -> 0.027982327 | K21: =SUM(K22:K24) -> 2.3333333 | ... P21: =SUM(P22:P24) -> 0.02970297
B22: Exits at EXCO | C22: =SUM(E22,G22,I22,K22,M22,O22) -> 0 | D22: =C22/$C$6 -> 0 | E22: =AVERAGE('Monthly Headcount'!E24,'Monthly Headcount'!E55,'Monthly Headcount'!E86) -> 0 | F22: =E22/$E$6 -> 0 | G22: =SUM('Monthly Headcount'!G24,'Monthly Headcount'!G55,'Monthly Headcount'!G86) -> 0 | H22: =G22/$G$6 -> 0 | I22: =AVERAGE('Monthly Headcount'!I24,'Monthly Headcount'!I55,'Monthly Headcount'!I86) -> 0 | J22: =I22/$I$6 -> 0 | K22: =AVERAGE('Monthly Headcount'!K24,'Monthly Headcount'!K55,'Monthly Headcount'!K86) -> 0 | L22: =K22/$K$6 -> 0 | M22: =AVERAGE('Monthly Headcount'!M24,'Monthly Headcount'!M55,'Monthly Headcount'!M86) -> 0 | N22: =M22/$M$6 -> 0 | O22: =AVERAGE('Monthly Headcount'!O24,'Monthly Headcount'!O55,'Monthly Headcount'!O86) -> 0 | P22: =O22/$O$6 -> 0
B23: Exits at EXCO - 1&2 | C23: =SUM(E23,G23,I23,K23,M23,O23) -> 3.3333333 | D23: =C23/$C$6 -> 0.0027731559 | E23: =AVERAGE('Monthly Headcount'!E25,'Monthly Headcount'!E56,'Monthly Headcount'!E87) -> 1.6666667 | F23: =E23/$E$6 -> 0.0027027027 | G23: =AVERAGE('Monthly Headcount'!G25,'Monthly Headcount'!G56,'Monthly Headcount'!G87) -> 0.66666667 | H23: =G23/$G$6 -> 0.0029455081 | I23: =AVERAGE('Monthly Headcount'!I25,'Monthly Headcount'!I56,'Monthly Headcount'!I87) -> 0.33333333 | J23: =I23/$I$6 -> 0.0014727541 | K23: =AVERAGE('Monthly Headcount'!K25,'Monthly Headcount'!K56,'Monthly Headcount'!K87) -> 0.66666667 | L23: =K23/$K$6 -> 0.016949153 | M23: =AVERAGE('Monthly Headcount'!M25,'Monthly Headcount'!M56,'Monthly Headcount'!M87) -> 0 | N23: =M23/$M$6 -> 0 | O23: =AVERAGE('Monthly Headcount'!O25,'Monthly Headcount'!O56,'Monthly Headcount'!O87) -> 0 | P23: =O23/$O$6 -> 0
B24: Exits at Other Levels | C24: =SUM(E24,G24,I24,K24,M24,O24) -> 23.333333 | D24: =C24/$C$6 -> 0.019412091 | E24: =AVERAGE('Monthly Headcount'!E26,'Monthly Headcount'!E57,'Monthly Headcount'!E88) -> 10.333333 | F24: =E24/$E$6 -> 0.016756757 | G24: =AVERAGE('Monthly Headcount'!G26,'Monthly Headcount'!G57,'Monthly Headcount'!G88) -> 3.3333333 | H24: =G24/$G$6 -> 0.014727541 | I24: =AVERAGE('Monthly Headcount'!I26,'Monthly Headcount'!I57,'Monthly Headcount'!I88) -> 6 | J24: =I24/$I$6 -> 0.026509573 | K24: =AVERAGE('Monthly Headcount'!K26,'Monthly Headcount'!K57,'Monthly Headcount'!K88) -> 1.6666667 | L24: =K24/$K$6 -> 0.042372881 | M24: =AVERAGE('Monthly Headcount'!M26,'Monthly Headcount'!M57,'Monthly Headcount'!M88) -> 1 | N24: =M24/$M$6 -> 0.016759777 | O24: =AVERAGE('Monthly Headcount'!O26,'Monthly Headcount'!O57,'Monthly Headcount'!O88) -> 1 | P24: =O24/$O$6 -> 0.02970297
B25: Total Internal Movements | C25: =SUM(E25,G25,I25,K25,M25,O25) -> 10.333333 | E25: =SUM(E26:E27) -> 5.3333333 | F25: =SUM(F26:F27) -> 0 | G25: =SUM(G26:G27) -> 0.66666667 | H25: =SUM(H26:H27) -> 0 | I25: =SUM(I26:I27) -> 2.6666667 | J25: =SUM(J26:J27) -> 0 | K25: =SUM(K26:K27) -> 0 | L25: =SUM(L26:L27) -> 0 | ... N25: =SUM(N26:N27) -> 0 | O25: =AVERAGE('Monthly Headcount'!O27,'Monthly Headcount'!O58,'Monthly Headcount'!O89) -> 0.66666667 | P25: =SUM(P26:P27) -> 0
B26: Promotions | C26: =SUM(E26,G26,I26,K26,M26,O26) -> 9.6666667 | E26: =AVERAGE('Monthly Headcount'!E28,'Monthly Headcount'!E59,'Monthly Headcount'!E90) -> 5 | G26: =AVERAGE('Monthly Headcount'!G28,'Monthly Headcount'!G59,'Monthly Headcount'!G90) -> 0.66666667 | I26: =AVERAGE('Monthly Headcount'!I28,'Monthly Headcount'!I59,'Monthly Headcount'!I90) -> 2.3333333 | K26: =AVERAGE('Monthly Headcount'!K28,'Monthly Headcount'!K59,'Monthly Headcount'!K90) -> 0 | M26: =AVERAGE('Monthly Headcount'!M28,'Monthly Headcount'!M59,'Monthly Headcount'!M90) -> 1 | O26: =AVERAGE('Monthly Headcount'!O28,'Monthly Headcount'!O59,'Monthly Headcount'!O90) -> 0.66666667
B27: Transfers | C27: =SUM(E27,G27,I27,K27,M27,O27) -> 0.66666667 | E27: =AVERAGE('Monthly Headcount'!E29,'Monthly Headcount'!E60,'Monthly Headcount'!E91) -> 0.33333333 | G27: =AVERAGE('Monthly Headcount'!G29,'Monthly Headcount'!G60,'Monthly Headcount'!G91) -> 0 | I27: =AVERAGE('Monthly Headcount'!I29,'Monthly Headcount'!I60,'Monthly Headcount'!I91) -> 0.33333333 | K27: =AVERAGE('Monthly Headcount'!K29,'Monthly Headcount'!K60,'Monthly Headcount'!K91) -> 0 | M27: =AVERAGE('Monthly Headcount'!M29,'Monthly Headcount'!M60,'Monthly Headcount'!M91) -> 0 | O27: =AVERAGE('Monthly Headcount'!O29,'Monthly Headcount'!O60,'Monthly Headcount'!O91) -> 0
B28: Principals | C28: =SUM(E28,G28,I28,K28,M28,O28) -> 411 | D28: =C28/C5 -> 0.19119243 | E28: =E29+E30 -> 337.33333 | F28: =E28/C28 -> 0.82076237 | G28: =G29+G30 -> 0 | H28: =G28/C28 -> 0 | I28: =I29+I30 -> 21.666667 | J28: =I28/C28 -> 0.052716951 | K28: =K29+K30 -> 36.666667 | L28: =K28/E28 -> 0.10869565 | M28: =M29+M30 -> 6 | N28: =M28/C28 -> 0.01459854 | O28: =O29+O30 -> 9.3333333 | P28: =O28/C28 -> 0.02270884
B29: Female | C29: =SUM(E29,G29,I29,K29,M29,O29) -> 120.33333 | D29: =C29/C28 -> 0.29278183 | E29: =AVERAGE('Monthly Headcount'!E31,'Monthly Headcount'!E62,'Monthly Headcount'!E93) -> 95.333333 | F29: =E29/E28 -> 0.2826087 | G29: =AVERAGE('Monthly Headcount'!G31,'Monthly Headcount'!G62,'Monthly Headcount'!G93) -> 0 | H29: 0 | I29: =AVERAGE('Monthly Headcount'!I31,'Monthly Headcount'!I62,'Monthly Headcount'!I93) -> 6 | J29: =I29/I28 -> 0.27692308 | K29: =AVERAGE('Monthly Headcount'!K31,'Monthly Headcount'!K62,'Monthly Headcount'!K93) -> 14.666667 | L29: =K29/K28 -> 0.4 | M29: =AVERAGE('Monthly Headcount'!M31,'Monthly Headcount'!M62,'Monthly Headcount'!M93) -> 1 | N29: =M29/M28 -> 0.16666667 | O29: =AVERAGE('Monthly Headcount'!O31,'Monthly Headcount'!O62,'Monthly Headcount'!O93) -> 3.3333333 | P29: 0
B30: Male | C30: =SUM(E30,G30,I30,K30,M30,O30) -> 290.66667 | D30: =C30/C28 -> 0.70721817 | E30: =AVERAGE('Monthly Headcount'!E32,'Monthly Headcount'!E63,'Monthly Headcount'!E94) -> 242 | F30: =E30/E28 -> 0.7173913 | G30: =AVERAGE('Monthly Headcount'!G32,'Monthly Headcount'!G63,'Monthly Headcount'!G94) -> 0 | H30: 0 | I30: =AVERAGE('Monthly Headcount'!I32,'Monthly Headcount'!I63,'Monthly Headcount'!I94) -> 15.666667 | J30: =I30/I28 -> 0.72307692 | K30: =AVERAGE('Monthly Headcount'!K32,'Monthly Headcount'!K63,'Monthly Headcount'!K94) -> 22 | L30: =K30/K28 -> 0.6 | M30: =AVERAGE('Monthly Headcount'!M32,'Monthly Headcount'!M63,'Monthly Headcount'!M94) -> 5 | N30: =M30/M28 -> 0.83333333 | O30: =AVERAGE('Monthly Headcount'!O32,'Monthly Headcount'!O63,'Monthly Headcount'!O94) -> 6 | P30: 0
B31: Casuals/Contractors | C31: =SUM(E31,G31,I31,K31,M31,O31) -> 536.66667 | D31: =C31/C5 -> 0.24965111 | E31: =E32+E33 -> 42.666667 | F31: =E31/C31 -> 0.079503106 | G31: =G32+G33 -> 494 | H31: =G31/C31 -> 0.92049689 | I31: =I32+I33 -> 0 | J31: 0 | K31: =K32+K33 -> 0 | L31: =K31/C31 -> 0 | M31: =M32+M33 -> 0 | N31: 0 | O31: =AVERAGE('Monthly Headcount'!O33,'Monthly Headcount'!O64,'Monthly Headcount'!O95) -> 0 | P31: 0
B32: Female | C32: =SUM(E32,G32,I32,K32,M32,O32) -> 229.33333 | D32: =C32/C31 -> 0.42732919 | E32: =AVERAGE('Monthly Headcount'!E34,'Monthly Headcount'!E65,'Monthly Headcount'!E96) -> 6 | F32: =E32/E31 -> 0.140625 | G32: =AVERAGE('Monthly Headcount'!G34,'Monthly Headcount'!G65,'Monthly Headcount'!G96) -> 223.33333 | H32: =G32/G31 -> 0.45209177 | I32: =AVERAGE('Monthly Headcount'!I34,'Monthly Headcount'!I65,'Monthly Headcount'!I96) -> 0 | J32: 0 | K32: =AVERAGE('Monthly Headcount'!K34,'Monthly Headcount'!K65,'Monthly Headcount'!K96) -> 0 | L32: 0 | M32: =AVERAGE('Monthly Headcount'!M34,'Monthly Headcount'!M65,'Monthly Headcount'!M96) -> 0 | N32: 0 | O32: =AVERAGE('Monthly Headcount'!O34,'Monthly Headcount'!O65,'Monthly Headcount'!O96) -> 0 | P32: 0
B33: Male | C33: =SUM(E33,G33,I33,K33,M33,O33) -> 307.33333 | D33: =C33/C31 -> 0.57267081 | E33: =AVERAGE('Monthly Headcount'!E35,'Monthly Headcount'!E66,'Monthly Headcount'!E97) -> 36.666667 | F33: =E33/E31 -> 0.859375 | G33: =AVERAGE('Monthly Headcount'!G35,'Monthly Headcount'!G66,'Monthly Headcount'!G97) -> 270.66667 | H33: =G33/G31 -> 0.54790823 | I33: =AVERAGE('Monthly Headcount'!I35,'Monthly Headcount'!I66,'Monthly Headcount'!I97) -> 0 | J33: 0 | K33: =AVERAGE('Monthly Headcount'!K35,'Monthly Headcount'!K66,'Monthly Headcount'!K97) -> 0 | L33: 0 | M33: =AVERAGE('Monthly Headcount'!M35,'Monthly Headcount'!M66,'Monthly Headcount'!M97) -> 0 | N33: 0 | O33: =AVERAGE('Monthly Headcount'!O35,'Monthly Headcount'!O66,'Monthly Headcount'!O97) -> 0 | P33: 0
A34: Q2 | B34: Overall Headcount | C34: =SUM(E34,G34,I34,K34,M34,O34) -> 2140 | D34: =SUM(F34,H34,J34,L34,N34,P34) -> 1 | E34: =SUM(E35,E57,E60) -> 949.66667 | F34: =E34/C34 -> 0.44376947 | G34: =SUM(G35,G57,G60) -> 760.33333 | H34: =G34/C34 -> 0.35529595 | I34: =SUM(I35,I57,I60) -> 254.66667 | J34: =I34/C34 -> 0.11900312 | K34: =SUM(K35,K57,K60) -> 71 | L34: =K34/C34 -> 0.03317757 | M34: =SUM(M35,M57,M60) -> 62.666667 | N34: =M34/C34 -> 0.029283489 | O34: =SUM(O35,O57,O60) -> 41.666667 | P34: =O34/C34 -> 0.019470405
B35: Direct Staff | C35: =SUM(E35,G35,I35,K35,M35,O35) -> 1173.3333 | D35: =C35/C34 -> 0.5482866 | E35: =E36+E37 -> 599.66667 | F35: =E35/C35 -> 0.51107955 | G35: =G36+G37 -> 223.66667 | H35: =G35/C35 -> 0.190625 | I35: =I36+I37 -> 222.33333 | J35: =I35/C35 -> 0.18948864 | K35: =K36+K37 -> 36.666667 | L35: =K35/C35 -> 0.03125 | M35: =M36+M37 -> 58 | N35: =M35/C35 -> 0.049431818 | O35: =O36+O37 -> 33 | P35: =O35/C35 -> 0.028125
B36: Female | C36: =SUM(E36,G36,I36,K36,M36,O36) -> 292.66667 | D36: =C36/C35 -> 0.24943182 | E36: =AVERAGE('Monthly Headcount'!E102,'Monthly Headcount'!E133,'Monthly Headcount'!E164) -> 134.33333 | F36: =E36/E35 -> 0.22401334 | G36: =AVERAGE('Monthly Headcount'!G102,'Monthly Headcount'!G133,'Monthly Headcount'!G164) -> 45.666667 | H36: =G36/G35 -> 0.20417288 | I36: =AVERAGE('Monthly Headcount'!I102,'Monthly Headcount'!I133,'Monthly Headcount'!I164) -> 64.666667 | J36: =I36/I35 -> 0.29085457 | K36: =AVERAGE('Monthly Headcount'!K102,'Monthly Headcount'!K133,'Monthly Headcount'!K164) -> 14.333333 | L36: =K36/K35 -> 0.39090909 | M36: =AVERAGE('Monthly Headcount'!M102,'Monthly Headcount'!M133,'Monthly Headcount'!M164) -> 16 | N36: =M36/M35 -> 0.27586207 | O36: =AVERAGE('Monthly Headcount'!O102,'Monthly Headcount'!O133,'Monthly Headcount'!O164) -> 17.666667 | P36: =O36/O35 -> 0.53535354
B37: Male | C37: =SUM(E37,G37,I37,K37,M37,O37) -> 880.66667 | D37: =C37/C35 -> 0.75056818 | E37: =AVERAGE('Monthly Headcount'!E103,'Monthly Headcount'!E134,'Monthly Headcount'!E165) -> 465.33333 | F37: =E37/E35 -> 0.77598666 | G37: =AVERAGE('Monthly Headcount'!G103,'Monthly Headcount'!G134,'Monthly Headcount'!G165) -> 178 | H37: =G37/G35 -> 0.79582712 | I37: =AVERAGE('Monthly Headcount'!I103,'Monthly Headcount'!I134,'Monthly Headcount'!I165) -> 157.66667 | J37: =I37/I35 -> 0.70914543 | K37: =AVERAGE('Monthly Headcount'!K103,'Monthly Headcount'!K134,'Monthly Headcount'!K165) -> 22.333333 | L37: =K37/K35 -> 0.60909091 | M37: =AVERAGE('Monthly Headcount'!M103,'Monthly Headcount'!M134,'Monthly Headcount'!M165) -> 42 | N37: =M37/M35 -> 0.72413793 | O37: =AVERAGE('Monthly Headcount'!O103,'Monthly Headcount'!O134,'Monthly Headcount'!O165) -> 15.333333 | P37: =O37/O35 -> 0.46464646
B38: Nationals | C38: =SUM(E38,G38,I38,K38,M38,O38) -> 1055.3333 | D38: =C38/C35 -> 0.89943182 | E38: =AVERAGE('Monthly Headcount'!E104,'Monthly Headcount'!E135,'Monthly Headcount'!E166) -> 517.33333 | F38: =E38/E35 -> 0.8627015 | G38: =AVERAGE('Monthly Headcount'!G104,'Monthly Headcount'!G135,'Monthly Headcount'!G166) -> 213 | H38: =G38/G35 -> 0.95230999 | I38: =AVERAGE('Monthly Headcount'!I104,'Monthly Headcount'!I135,'Monthly Headcount'!I166) -> 207.33333 | J38: =I38/I35 -> 0.93253373 | K38: =AVERAGE('Monthly Headcount'!K104,'Monthly Headcount'!K135,'Monthly Headcount'!K166) -> 33 | L38: =K38/K35 -> 0.9 | M38: =AVERAGE('Monthly Headcount'!M104,'Monthly Headcount'!M135,'Monthly Headcount'!M166) -> 52.666667 | N38: =M38/M35 -> 0.90804598 | O38: =AVERAGE('Monthly Headcount'!O104,'Monthly Headcount'!O135,'Monthly Headcount'!O166) -> 32 | P38: =O38/O35 -> 0.96969697
B39: Expatriates | C39: =SUM(E39,G39,I39,K39,M39,O39) -> 118.66667 | D39: =C39/C35 -> 0.10113636 | E39: =AVERAGE('Monthly Headcount'!E105,'Monthly Headcount'!E136,'Monthly Headcount'!E167) -> 82.333333 | F39: =E39/E35 -> 0.1372985 | G39: =AVERAGE('Monthly Headcount'!G105,'Monthly Headcount'!G136,'Monthly Headcount'!G167) -> 10.666667 | H39: =G39/G35 -> 0.047690015 | I39: =AVERAGE('Monthly Headcount'!I105,'Monthly Headcount'!I136,'Monthly Headcount'!I167) -> 15 | J39: =I39/I35 -> 0.067466267 | K39: =AVERAGE('Monthly Headcount'!K105,'Monthly Headcount'!K136,'Monthly Headcount'!K167) -> 3.6666667 | L39: =K39/K35 -> 0.1 | M39: =AVERAGE('Monthly Headcount'!M105,'Monthly Headcount'!M136,'Monthly Headcount'!M167) -> 6 | N39: =M39/M35 -> 0.10344828 | O39: =AVERAGE('Monthly Headcount'!O105,'Monthly Headcount'!O136,'Monthly Headcount'!O167) -> 1 | P39: =O39/O35 -> 0.03030303
B40: Management | C40: =SUM(E40,G40,I40,K40,M40,O40) -> 255.33333 | D40: =C40/C35 -> 0.21761364 | E40: =AVERAGE('Monthly Headcount'!E106,'Monthly Headcount'!E137,'Monthly Headcount'!E168) -> 122.33333 | F40: =E40/E35 -> 0.20400222 | G40: =AVERAGE('Monthly Headcount'!G106,'Monthly Headcount'!G137,'Monthly Headcount'!G168) -> 57.333333 | H40: =G40/G35 -> 0.25633383 | I40: =AVERAGE('Monthly Headcount'!I106,'Monthly Headcount'!I137,'Monthly Headcount'!I168) -> 41.666667 | J40: =I40/I35 -> 0.1874063 | K40: =AVERAGE('Monthly Headcount'!K106,'Monthly Headcount'!K137,'Monthly Headcount'!K168) -> 11 | L40: =K40/K35 -> 0.3 | M40: =AVERAGE('Monthly Headcount'!M106,'Monthly Headcount'!M137,'Monthly Headcount'!M168) -> 16 | N40: =M40/M35 -> 0.27586207 | O40: =AVERAGE('Monthly Headcount'!O106,'Monthly Headcount'!O137,'Monthly Headcount'!O168) -> 7 | P40: =O40/O35 -> 0.21212121
B41: Female in Management | C41: =SUM(E41,G41,I41,K41,M41,O41) -> 46 | D41: =C41/C40 -> 0.18015666 | E41: =AVERAGE('Monthly Headcount'!E107,'Monthly Headcount'!E138,'Monthly Headcount'!E169) -> 21 | F41: =E41/E40 -> 0.17166213 | G41: =AVERAGE('Monthly Headcount'!G107,'Monthly Headcount'!G138,'Monthly Headcount'!G169) -> 8.6666667 | H41: =G41/G40 -> 0.15116279 | I41: =AVERAGE('Monthly Headcount'!I107,'Monthly Headcount'!I138,'Monthly Headcount'!I169) -> 7.3333333 | J41: =I41/I40 -> 0.176 | K41: =AVERAGE('Monthly Headcount'!K107,'Monthly Headcount'!K138,'Monthly Headcount'!K169) -> 3 | L41: =K41/K40 -> 0.27272727 | M41: =AVERAGE('Monthly Headcount'!M107,'Monthly Headcount'!M138,'Monthly Headcount'!M169) -> 4 | N41: =M41/M40 -> 0.25 | O41: =AVERAGE('Monthly Headcount'!O107,'Monthly Headcount'!O138,'Monthly Headcount'!O169) -> 2 | P41: =O41/O40 -> 0.28571429
...

Sheet Copy YTD Headcount-Board
B1: Group | D1: Uganda | F1: APDL | H1: Tanzania | J1: Rwanda | L1: Burundi | N1: Kenya
B2: Number | C2: % | D2: Number | E2: % | F2: Number | G2: % | H2: Number | I2: % | J2: Number | K2: % | L2: Number | M2: % | N2: Number | O2: %
A4: Overall Headcount | B4: =SUM(D4,F4,H4,J4,L4,N4) -> 2149.6667 | C4: =SUM(E4,G4,I4,K4,M4,O4) -> 1 | D4: =SUM(D5,D27,D30) -> 996.66667 | E4: =D4/B$4 -> 0.46363777 | F4: =SUM(F5,F27,F30) -> 720.33333 | G4: =F4/B$4 -> 0.33509071 | H4: =SUM(H5,H27,H30) -> 248 | I4: =H4/B$4 -> 0.11536672 | J4: =SUM(J5,J27,J30) -> 76 | K4: =J4/B$4 -> 0.035354318 | L4: =SUM(L5,L27,L30) -> 65.666667 | M4: =L4/B$4 -> 0.030547372 | N4: =SUM(N5,N27,N30) -> 43 | O4: =N4/B$4 -> 0.020003101
A5: Direct Staff | B5: =SUM(D5,F5,H5,J5,L5,N5) -> 1202 | C5: =B5/B4 -> 0.55915646 | D5: =D6+D7 -> 616.66667 | E5: =D5/B5 -> 0.51303383 | F5: =F6+F7 -> 226.33333 | G5: =F5/B5 -> 0.18829728 | H5: =H6+H7 -> 226.33333 | I5: =H5/B5 -> 0.18829728 | J5: =J6+J7 -> 39.333333 | K5: =J5/B5 -> 0.032723239 | L5: =L6+L7 -> 59.666667 | M5: =L5/B5 -> 0.04963949 | N5: =N6+N7 -> 33.666667 | O5: =N5/B5 -> 0.028008874
A6: Female | B6: =SUM(D6,F6,H6,J6,L6,N6) -> 307.33333 | C6: =B6/B5 -> 0.25568497 | D6: =AVERAGE('Monthly Headcount'!E9,'Monthly Headcount'!E40,'Monthly Headcount'!E71) -> 146 | E6: =D6/D5 -> 0.23675676 | F6: =AVERAGE('Monthly Headcount'!G9,'Monthly Headcount'!G40,'Monthly Headcount'!G71) -> 45 | G6: =F6/F5 -> 0.1988218 | H6: =AVERAGE('Monthly Headcount'!I9,'Monthly Headcount'!I40,'Monthly Headcount'!I71) -> 67.333333 | I6: =H6/H5 -> 0.29749632 | J6: =AVERAGE('Monthly Headcount'!K9,'Monthly Headcount'!K40,'Monthly Headcount'!K71) -> 14 | K6: =J6/J5 -> 0.3559322 | L6: =AVERAGE('Monthly Headcount'!M9,'Monthly Headcount'!M40,'Monthly Headcount'!M71) -> 17.666667 | M6: =L6/L5 -> 0.29608939 | N6: =AVERAGE('Monthly Headcount'!O9,'Monthly Headcount'!O40,'Monthly Headcount'!O71) -> 17.333333 | O6: =N6/N5 -> 0.51485149
A7: Male | B7: =SUM(D7,F7,H7,J7,L7,N7) -> 894.66667 | C7: =B7/B5 -> 0.74431503 | D7: =AVERAGE('Monthly Headcount'!E10,'Monthly Headcount'!E41,'Monthly Headcount'!E72) -> 470.66667 | E7: =D8/D5 -> 0.86324324 | F7: =AVERAGE('Monthly Headcount'!G10,'Monthly Headcount'!G41,'Monthly Headcount'!G72) -> 181.33333 | G7: =F7/F5 -> 0.8011782 | H7: =AVERAGE('Monthly Headcount'!I10,'Monthly Headcount'!I41,'Monthly Headcount'!I72) -> 159 | I7: =H7/H5 -> 0.70250368 | J7: =AVERAGE('Monthly Headcount'!K10,'Monthly Headcount'!K41,'Monthly Headcount'!K72) -> 25.333333 | K7: =J7/J5 -> 0.6440678 | L7: =AVERAGE('Monthly Headcount'!M10,'Monthly Headcount'!M41,'Monthly Headcount'!M72) -> 42 | M7: =L7/L5 -> 0.70391061 | N7: =AVERAGE('Monthly Headcount'!O10,'Monthly Headcount'!O41,'Monthly Headcount'!O72) -> 16.333333 | O7: =N7/N5 -> 0.48514851
A8: Nationals | B8: =SUM(D8,F8,H8,J8,L8,N8) -> 1080.3333 | C8: =B8/B5 -> 0.89877981 | D8: =AVERAGE('Monthly Headcount'!E11,'Monthly Headcount'!E42,'Monthly Headcount'!E73) -> 532.33333 | E8: =D8/D5 -> 0.86324324 | F8: =AVERAGE('Monthly Headcount'!G11,'Monthly Headcount'!G42,'Monthly Headcount'!G73) -> 214.33333 | G8: =F8/F5 -> 0.94698085 | H8: =AVERAGE('Monthly Headcount'!I11,'Monthly Headcount'!I42,'Monthly Headcount'!I73) -> 211.33333 | I8: =H8/H5 -> 0.93372607 | J8: =AVERAGE('Monthly Headcount'!K11,'Monthly Headcount'!K42,'Monthly Headcount'!K73) -> 35 | K8: =J8/J5 -> 0.88983051 | L8: =AVERAGE('Monthly Headcount'!M11,'Monthly Headcount'!M42,'Monthly Headcount'!M73) -> 54.666667 | M8: =L8/L5 -> 0.91620112 | N8: =AVERAGE('Monthly Headcount'!O11,'Monthly Headcount'!O42,'Monthly Headcount'!O73) -> 32.666667 | O8: =N8/N5 -> 0.97029703
A9: Expatriates | B9: =SUM(D9,F9,H9,J9,L9,N9) -> 121.66667 | C9: =B9/B5 -> 0.10122019 | D9: =AVERAGE('Monthly Headcount'!E12,'Monthly Headcount'!E43,'Monthly Headcount'!E74) -> 84.333333 | E9: =D9/D5 -> 0.13675676 | F9: =AVERAGE('Monthly Headcount'!G12,'Monthly Headcount'!G43,'Monthly Headcount'!G74) -> 12 | G9: =F9/F5 -> 0.053019146 | H9: =AVERAGE('Monthly Headcount'!I12,'Monthly Headcount'!I43,'Monthly Headcount'!I74) -> 15 | I9: =H9/H5 -> 0.066273932 | J9: =AVERAGE('Monthly Headcount'!K12,'Monthly Headcount'!K43,'Monthly Headcount'!K74) -> 4.3333333 | K9: =J9/J5 -> 0.11016949 | L9: =AVERAGE('Monthly Headcount'!M12,'Monthly Headcount'!M43,'Monthly Headcount'!M74) -> 5 | M9: =L9/L5 -> 0.083798883 | N9: =AVERAGE('Monthly Headcount'!O12,'Monthly Headcount'!O43,'Monthly Headcount'!O74) -> 1 | O9: =N9/N5 -> 0.02970297
A10: Management | B10: =SUM(D10,F10,H10,J10,L10,N10) -> 266.33333 | C10: =B10/B5 -> 0.22157515 | D10: =AVERAGE('Monthly Headcount'!E13,'Monthly Headcount'!E44,'Monthly Headcount'!E75) -> 126.66667 | E10: =D10/D5 -> 0.20540541 | F10: =AVERAGE('Monthly Headcount'!G13,'Monthly Headcount'!G44,'Monthly Headcount'!G75) -> 64 | G10: =F10/F5 -> 0.28276878 | H10: =AVERAGE('Monthly Headcount'!I13,'Monthly Headcount'!I44,'Monthly Headcount'!I75) -> 41 | I10: =H10/H5 -> 0.18114875 | J10: =AVERAGE('Monthly Headcount'!K13,'Monthly Headcount'!K44,'Monthly Headcount'!K75) -> 11.333333 | K10: =J10/J5 -> 0.28813559 | L10: =AVERAGE('Monthly Headcount'!M13,'Monthly Headcount'!M44,'Monthly Headcount'!M75) -> 16.333333 | M10: =L10/L5 -> 0.27374302 | N10: =AVERAGE('Monthly Headcount'!O13,'Monthly Headcount'!O44,'Monthly Headcount'!O75) -> 7 | O10: =N10/N5 -> 0.20792079
A11: Female in Management | B11: =SUM(D11,F11,H11,J11,L11,N11) -> 44.666667 | C11: =B11/B10 -> 0.16770964 | D11: =AVERAGE('Monthly Headcount'!E14,'Monthly Headcount'!E45,'Monthly Headcount'!E76) -> 18.666667 | E11: =D11/D10 -> 0.14736842 | F11: =AVERAGE('Monthly Headcount'!G14,'Monthly Headcount'!G45,'Monthly Headcount'!G76) -> 9.3333333 | G11: =F11/F10 -> 0.14583333 | H11: =AVERAGE('Monthly Headcount'!I14,'Monthly Headcount'!I45,'Monthly Headcount'!I76) -> 8 | I11: =H11/H10 -> 0.19512195 | J11: =AVERAGE('Monthly Headcount'!K14,'Monthly Headcount'!K45,'Monthly Headcount'!K76) -> 2.6666667 | K11: =J11/J10 -> 0.23529412 | L11: =AVERAGE('Monthly Headcount'!M14,'Monthly Headcount'!M45,'Monthly Headcount'!M76) -> 4 | M11: =L11/L10 -> 0.24489796 | N11: =AVERAGE('Monthly Headcount'!O14,'Monthly Headcount'!O45,'Monthly Headcount'!O76) -> 2 | O11: =N11/N10 -> 0.28571429
A12: Below 40 years of age | B12: =SUM(D12,F12,H12,J12,L12,N12) -> 950.66667 | C12: =B12/B5 -> 0.79090405 | D12: =AVERAGE('Monthly Headcount'!E15,'Monthly Headcount'!E46,'Monthly Headcount'!E77) -> 473.66667 | E12: =D12/D5 -> 0.76810811 | F12: =AVERAGE('Monthly Headcount'!G15,'Monthly Headcount'!G46,'Monthly Headcount'!G77) -> 184.33333 | G12: =F12/F5 -> 0.81443299 | H12: =AVERAGE('Monthly Headcount'!I15,'Monthly Headcount'!I46,'Monthly Headcount'!I77) -> 184.33333 | I12: =H12/H5 -> 0.81443299 | J12: =AVERAGE('Monthly Headcount'!K15,'Monthly Headcount'!K46,'Monthly Headcount'!K77) -> 33.666667 | K12: =J12/J5 -> 0.8559322 | L12: =AVERAGE('Monthly Headcount'!M15,'Monthly Headcount'!M46,'Monthly Headcount'!M77) -> 48.666667 | M12: =L12/L5 -> 0.81564246 | N12: =AVERAGE('Monthly Headcount'!O15,'Monthly Headcount'!O46,'Monthly Headcount'!O77) -> 26 | O12: =N12/N5 -> 0.77227723
A13: Atleast 40 years of age | B13: =SUM(D13,F13,H13,J13,L13,N13) -> 251.33333 | C13: =B13/B5 -> 0.20909595 | D13: =AVERAGE('Monthly Headcount'!E16,'Monthly Headcount'!E47,'Monthly Headcount'!E78) -> 143 | E13: =D13/D5 -> 0.23189189 | F13: =AVERAGE('Monthly Headcount'!G16,'Monthly Headcount'!G47,'Monthly Headcount'!G78) -> 42 | G13: =F13/F5 -> 0.18556701 | H13: =AVERAGE('Monthly Headcount'!I16,'Monthly Headcount'!I47,'Monthly Headcount'!I78) -> 42 | I13: =H13/H5 -> 0.18556701 | J13: =AVERAGE('Monthly Headcount'!K16,'Monthly Headcount'!K47,'Monthly Headcount'!K78) -> 5.6666667 | K13: =J13/J5 -> 0.1440678 | L13: =AVERAGE('Monthly Headcount'!M16,'Monthly Headcount'!M47,'Monthly Headcount'!M78) -> 11 | M13: =L13/L5 -> 0.18435754 | N13: =AVERAGE('Monthly Headcount'!O16,'Monthly Headcount'!O47,'Monthly Headcount'!O78) -> 7.6666667 | O13: =N13/N5 -> 0.22772277
A14: Less than 5 years with Abacus | B14: =SUM(D14,F14,H14,J14,L14,N14) -> 685.66667 | C14: =B14/B5 -> 0.57043816 | D14: =AVERAGE('Monthly Headcount'!E17,'Monthly Headcount'!E48,'Monthly Headcount'!E79) -> 365.66667 | E14: =D14/D5 -> 0.59297297 | F14: =AVERAGE('Monthly Headcount'!G17,'Monthly Headcount'!G48,'Monthly Headcount'!G79) -> 92 | G14: =F14/F5 -> 0.40648012 | H14: =AVERAGE('Monthly Headcount'!I17,'Monthly Headcount'!I48,'Monthly Headcount'!I79) -> 143 | I14: =H14/H5 -> 0.63181149 | J14: =AVERAGE('Monthly Headcount'!K17,'Monthly Headcount'!K48,'Monthly Headcount'!K79) -> 29.333333 | K14: =J14/J5 -> 0.74576271 | L14: =AVERAGE('Monthly Headcount'!M17,'Monthly Headcount'!M48,'Monthly Headcount'!M79) -> 30.333333 | M14: =L14/L5 -> 0.50837989 | N14: =AVERAGE('Monthly Headcount'!O17,'Monthly Headcount'!O48,'Monthly Headcount'!O79) -> 25.333333 | O14: =N14/N5 -> 0.75247525
A15: Atleast 5 years with Abacus | B15: =SUM(D15,F15,H15,J15,L15,N15) -> 516.33333 | C15: =B15/B5 -> 0.42956184 | D15: =AVERAGE('Monthly Headcount'!E18,'Monthly Headcount'!E49,'Monthly Headcount'!E80) -> 251 | E15: =D15/D5 -> 0.40702703 | F15: =AVERAGE('Monthly Headcount'!G18,'Monthly Headcount'!G49,'Monthly Headcount'!G80) -> 134.33333 | G15: =F15/F5 -> 0.59351988 | H15: =AVERAGE('Monthly Headcount'!I18,'Monthly Headcount'!I49,'Monthly Headcount'!I80) -> 83.333333 | I15: =H15/H5 -> 0.36818851 | J15: =AVERAGE('Monthly Headcount'!K18,'Monthly Headcount'!K49,'Monthly Headcount'!K80) -> 10 | K15: =J15/J5 -> 0.25423729 | L15: =AVERAGE('Monthly Headcount'!M18,'Monthly Headcount'!M49,'Monthly Headcount'!M80) -> 29.333333 | M15: =L15/L5 -> 0.49162011 | N15: =AVERAGE('Monthly Headcount'!O18,'Monthly Headcount'!O49,'Monthly Headcount'!O80) -> 8.3333333 | O15: =N15/N5 -> 0.24752475
A16: Total New hires | B16: =SUM(D16,F16,H16,J16,L16,N16) -> 65.333333 | C16: =SUM(C17:C19) -> 0.054353855 | D16: =SUM(D17:D19) -> 20 | E16: =SUM(E17:E19) -> 0.032432432 | F16: =SUM(F17:F19) -> 7 | G16: =SUM(G17:G19) -> 0.0058236273 | H16: =SUM(H17:H19) -> 29.333333 | I16: =SUM(I17:I19) -> 0.024403771 | J16: =SUM(J17:J19) -> 2 | ... O16: =SUM(O17:O19) -> 0.0049916805
A17: New hires at EXCO | B17: =SUM(D17,F17,H17,J17,L17,N17) -> 1 | C17: =B17/$B$5 -> 0.00083194676 | D17: 1 | E17: =D17/$D$5 -> 0.0016216216 | F17: =AVERAGE('Monthly Headcount'!G20,'Monthly Headcount'!G51,'Monthly Headcount'!G82) -> 0 | G17: =F17/$B$5 -> 0 | H17: =AVERAGE('Monthly Headcount'!I20,'Monthly Headcount'!I51,'Monthly Headcount'!I82) -> 0 | I17: =H17/$B$5 -> 0 | J17: =AVERAGE('Monthly Headcount'!K20,'Monthly Headcount'!K51,'Monthly Headcount'!K82) -> 0 | K17: =J17/$B$5 -> 0 | L17: =AVERAGE('Monthly Headcount'!M20,'Monthly Headcount'!M51,'Monthly Headcount'!M82) -> 0 | M17: =L17/$B$5 -> 0 | N17: =AVERAGE('Monthly Headcount'!O20,'Monthly Headcount'!O51,'Monthly Headcount'!O82) -> 0 | O17: =N17/$B$5 -> 0
A18: New hires at EXCO - 1&2 | B18: =SUM(D18,F18,H18,J18,L18,N18) -> 2.3333333 | C18: =B18/$B$5 -> 0.0019412091 | D18: =AVERAGE('Monthly Headcount'!E21,'Monthly Headcount'!E52,'Monthly Headcount'!E83) -> 0 | E18: =D18/$D$5 -> 0 | F18: =AVERAGE('Monthly Headcount'!G21,'Monthly Headcount'!G52,'Monthly Headcount'!G83) -> 0 | G18: =F18/$B$5 -> 0 | H18: =AVERAGE('Monthly Headcount'!I21,'Monthly Headcount'!I52,'Monthly Headcount'!I83) -> 0.33333333 | I18: =H18/$B$5 -> 0.00027731559 | J18: 2 | K18: =J18/$B$5 -> 0.0016638935 | L18: =AVERAGE('Monthly Headcount'!M21,'Monthly Headcount'!M52,'Monthly Headcount'!M83) -> 0 | M18: =L18/$B$5 -> 0 | N18: =AVERAGE('Monthly Headcount'!O21,'Monthly Headcount'!O52,'Monthly Headcount'!O83) -> 0 | O18: =N18/$B$5 -> 0
A19: New hires at Other Levels | B19: =SUM(D19,F19,H19,J19,L19,N19) -> 62 | C19: =B19/$B$5 -> 0.051580699 | D19: 19 | E19: =D19/$D$5 -> 0.030810811 | F19: 7 | G19: =F19/$B$5 -> 0.0058236273 | H19: 29 | I19: =H19/$B$5 -> 0.024126456 | J19: 0 | K19: =J19/$B$5 -> 0 | L19: 1 | M19: =L19/$B$5 -> 0.00083194676 | N19: 6 | O19: =N19/$B$5 -> 0.0049916805
A20: Total Exits | B20: =SUM(D20,F20,H20,J20,L20,N20) -> 77 | C20: =SUM(C21:C23) -> 0.0640599 | D20: =SUM(D21:D23) -> 36 | E20: =SUM(E21:E23) -> 0.058378378 | F20: =SUM(F21:F23) -> 12 | G20: =SUM(G21:G23) -> 0.053019146 | H20: =SUM(H21:H23) -> 19 | I20: =SUM(I21:I23) -> 0.083946981 | J20: =SUM(J21:J23) -> 4 | ... O20: =SUM(O21:O23) -> 0.089108911
A21: Exits at EXCO | B21: =SUM(D21,F21,H21,J21,L21,N21) -> 0 | C21: =B21/$B$5 -> 0 | D21: =AVERAGE('Monthly Headcount'!E24,'Monthly Headcount'!E55,'Monthly Headcount'!E86) -> 0 | E21: =D21/$D$5 -> 0 | F21: =SUM('Monthly Headcount'!G24,'Monthly Headcount'!G55,'Monthly Headcount'!G86) -> 0 | G21: =F21/$F$5 -> 0 | H21: =AVERAGE('Monthly Headcount'!I24,'Monthly Headcount'!I55,'Monthly Headcount'!I86) -> 0 | I21: =H21/$H$5 -> 0 | J21: =AVERAGE('Monthly Headcount'!K24,'Monthly Headcount'!K55,'Monthly Headcount'!K86) -> 0 | K21: =J21/$J$5 -> 0 | L21: =AVERAGE('Monthly Headcount'!M24,'Monthly Headcount'!M55,'Monthly Headcount'!M86) -> 0 | M21: =L21/$L$5 -> 0 | N21: =AVERAGE('Monthly Headcount'!O24,'Monthly Headcount'!O55,'Monthly Headcount'!O86) -> 0 | O21: =N21/$N$5 -> 0
A22: Exits at EXCO - 1&2 | B22: =SUM(D22,F22,H22,J22,L22,N22) -> 9 | C22: =B22/$B$5 -> 0.0074875208 | D22: 4 | E22: =D22/$D$5 -> 0.0064864865 | F22: 2 | G22: =F22/$F$5 -> 0.0088365243 | H22: 1 | I22: =H22/$H$5 -> 0.0044182622 | J22: 2 | K22: =J22/$J$5 -> 0.050847458 | L22: =AVERAGE('Monthly Headcount'!M25,'Monthly Headcount'!M56,'Monthly Headcount'!M87) -> 0 | M22: =L22/$L$5 -> 0 | N22: =AVERAGE('Monthly Headcount'!O25,'Monthly Headcount'!O56,'Monthly Headcount'!O87) -> 0 | O22: =N22/$N$5 -> 0
A23: Exits at Other Levels | B23: =SUM(D23,F23,H23,J23,L23,N23) -> 68 | C23: =B23/$B$5 -> 0.056572379 | D23: 32 | E23: =D23/$D$5 -> 0.051891892 | F23: 10 | G23: =F23/$F$5 -> 0.044182622 | H23: 18 | I23: =H23/$H$5 -> 0.079528719 | J23: 2 | K23: =J23/$J$5 -> 0.050847458 | L23: 3 | M23: =L23/$L$5 -> 0.05027933 | N23: 3 | O23: =N23/$N$5 -> 0.089108911
A24: Total Internal Movements | B24: 31 | C24: =SUM(C25:C26) -> 0.025790349 | D24: =SUM(D25:D26) -> 16 | E24: =SUM(E25:E26) -> 0.013311148 | F24: =SUM(F25:F26) -> 2 | G24: =SUM(G25:G26) -> 0.0016638935 | H24: =SUM(H25:H26) -> 8 | I24: =SUM(I25:I26) -> 0.006655574 | J24: =SUM(J25:J26) -> 0 | ... M24: =SUM(M25:M26) -> 0.0024958403 | N24: =AVERAGE('Monthly Headcount'!O27,'Monthly Headcount'!O58,'Monthly Headcount'!O89) -> 0.66666667 | O24: =SUM(O25:O26) -> 0.0016638935
A25: Promotions | B25: =SUM(D25,F25,H25,J25,L25,N25) -> 29 | C25: =B25/$B$5 -> 0.024126456 | D25: 15 | E25: =D25/$B$5 -> 0.012479201 | F25: 2 | G25: =F25/$B$5 -> 0.0016638935 | H25: 7 | I25: =H25/$B$5 -> 0.0058236273 | J25: =AVERAGE('Monthly Headcount'!K28,'Monthly Headcount'!K59,'Monthly Headcount'!K90) -> 0 | K25: =J25/$B$5 -> 0 | L25: 3 | M25: =L25/$B$5 -> 0.0024958403 | N25: 2 | O25: =N25/$B$5 -> 0.0016638935
A26: Transfers | B26: =SUM(D26,F26,H26,J26,L26,N26) -> 2 | C26: =B26/$B$5 -> 0.0016638935 | D26: 1 | E26: =D26/$B$5 -> 0.00083194676 | F26: =AVERAGE('Monthly Headcount'!G29,'Monthly Headcount'!G60,'Monthly Headcount'!G91) -> 0 | G26: =F26/$B$5 -> 0 | H26: 1 | I26: =H26/$B$5 -> 0.00083194676 | J26: =AVERAGE('Monthly Headcount'!K29,'Monthly Headcount'!K60,'Monthly Headcount'!K91) -> 0 | K26: =J26/$B$5 -> 0 | L26: =AVERAGE('Monthly Headcount'!M29,'Monthly Headcount'!M60,'Monthly Headcount'!M91) -> 0 | M26: =L26/$B$5 -> 0 | N26: =AVERAGE('Monthly Headcount'!O29,'Monthly Headcount'!O60,'Monthly Headcount'!O91) -> 0 | O26: =N26/$B$5 -> 0
A27: Principals | B27: =SUM(D27,F27,H27,J27,L27,N27) -> 411 | C27: =B27/B4 -> 0.19119243 | D27: =D28+D29 -> 337.33333 | E27: =D27/B27 -> 0.82076237 | F27: =F28+F29 -> 0 | G27: =F27/B27 -> 0 | H27: =H28+H29 -> 21.666667 | I27: =H27/B27 -> 0.052716951 | J27: =J28+J29 -> 36.666667 | K27: =J27/D27 -> 0.10869565 | L27: =L28+L29 -> 6 | M27: =L27/B27 -> 0.01459854 | N27: =N28+N29 -> 9.3333333 | O27: =N27/B27 -> 0.02270884
A28: Female | B28: =SUM(D28,F28,H28,J28,L28,N28) -> 120.33333 | C28: =B28/B27 -> 0.29278183 | D28: =AVERAGE('Monthly Headcount'!E31,'Monthly Headcount'!E62,'Monthly Headcount'!E93) -> 95.333333 | E28: =D28/D27 -> 0.2826087 | F28: =AVERAGE('Monthly Headcount'!G31,'Monthly Headcount'!G62,'Monthly Headcount'!G93) -> 0 | G28: 0 | H28: =AVERAGE('Monthly Headcount'!I31,'Monthly Headcount'!I62,'Monthly Headcount'!I93) -> 6 | I28: =H28/H27 -> 0.27692308 | J28: =AVERAGE('Monthly Headcount'!K31,'Monthly Headcount'!K62,'Monthly Headcount'!K93) -> 14.666667 | K28: =J28/J27 -> 0.4 | L28: =AVERAGE('Monthly Headcount'!M31,'Monthly Headcount'!M62,'Monthly Headcount'!M93) -> 1 | M28: =L28/L27 -> 0.16666667 | N28: =AVERAGE('Monthly Headcount'!O31,'Monthly Headcount'!O62,'Monthly Headcount'!O93) -> 3.3333333 | O28: 0
A29: Male | B29: =SUM(D29,F29,H29,J29,L29,N29) -> 290.66667 | C29: =B29/B27 -> 0.70721817 | D29: =AVERAGE('Monthly Headcount'!E32,'Monthly Headcount'!E63,'Monthly Headcount'!E94) -> 242 | E29: =D29/D27 -> 0.7173913 | F29: =AVERAGE('Monthly Headcount'!G32,'Monthly Headcount'!G63,'Monthly Headcount'!G94) -> 0 | G29: 0 | H29: =AVERAGE('Monthly Headcount'!I32,'Monthly Headcount'!I63,'Monthly Headcount'!I94) -> 15.666667 | I29: =H29/H27 -> 0.72307692 | J29: =AVERAGE('Monthly Headcount'!K32,'Monthly Headcount'!K63,'Monthly Headcount'!K94) -> 22 | K29: =J29/J27 -> 0.6 | L29: =AVERAGE('Monthly Headcount'!M32,'Monthly Headcount'!M63,'Monthly Headcount'!M94) -> 5 | M29: =L29/L27 -> 0.83333333 | N29: =AVERAGE('Monthly Headcount'!O32,'Monthly Headcount'!O63,'Monthly Headcount'!O94) -> 6 | O29: 0
A30: Casuals/Contractors | B30: =SUM(D30,F30,H30,J30,L30,N30) -> 536.66667 | C30: =B30/B4 -> 0.24965111 | D30: =D31+D32 -> 42.666667 | E30: =D30/B30 -> 0.079503106 | F30: =F31+F32 -> 494 | G30: =F30/B30 -> 0.92049689 | H30: =H31+H32 -> 0 | I30: 0 | J30: =J31+J32 -> 0 | K30: =J30/B30 -> 0 | L30: =L31+L32 -> 0 | M30: 0 | N30: =AVERAGE('Monthly Headcount'!O33,'Monthly Headcount'!O64,'Monthly Headcount'!O95) -> 0 | O30: 0
A31: Female | B31: =SUM(D31,F31,H31,J31,L31,N31) -> 229.33333 | C31: =B31/B30 -> 0.42732919 | D31: =AVERAGE('Monthly Headcount'!E34,'Monthly Headcount'!E65,'Monthly Headcount'!E96) -> 6 | E31: =D31/D30 -> 0.140625 | F31: =AVERAGE('Monthly Headcount'!G34,'Monthly Headcount'!G65,'Monthly Headcount'!G96) -> 223.33333 | G31: =F31/F30 -> 0.45209177 | H31: =AVERAGE('Monthly Headcount'!I34,'Monthly Headcount'!I65,'Monthly Headcount'!I96) -> 0 | I31: 0 | J31: =AVERAGE('Monthly Headcount'!K34,'Monthly Headcount'!K65,'Monthly Headcount'!K96) -> 0 | K31: 0 | L31: =AVERAGE('Monthly Headcount'!M34,'Monthly Headcount'!M65,'Monthly Headcount'!M96) -> 0 | M31: 0 | N31: =AVERAGE('Monthly Headcount'!O34,'Monthly Headcount'!O65,'Monthly Headcount'!O96) -> 0 | O31: 0
A32: Male | B32: =SUM(D32,F32,H32,J32,L32,N32) -> 307.33333 | C32: =B32/B30 -> 0.57267081 | D32: =AVERAGE('Monthly Headcount'!E35,'Monthly Headcount'!E66,'Monthly Headcount'!E97) -> 36.666667 | E32: =D32/D30 -> 0.859375 | F32: =AVERAGE('Monthly Headcount'!G35,'Monthly Headcount'!G66,'Monthly Headcount'!G97) -> 270.66667 | G32: =F32/F30 -> 0.54790823 | H32: =AVERAGE('Monthly Headcount'!I35,'Monthly Headcount'!I66,'Monthly Headcount'!I97) -> 0 | I32: 0 | J32: =AVERAGE('Monthly Headcount'!K35,'Monthly Headcount'!K66,'Monthly Headcount'!K97) -> 0 | K32: 0 | L32: =AVERAGE('Monthly Headcount'!M35,'Monthly Headcount'!M66,'Monthly Headcount'!M97) -> 0 | M32: 0 | N32: =AVERAGE('Monthly Headcount'!O35,'Monthly Headcount'!O66,'Monthly Headcount'!O97) -> 0 | O32: 0
B34: Group | D34: Uganda | F34: APDL | H34: Tanzania | J34: Rwanda | L34: Burundi | N34: Kenya
B35: Number | C35: % | D35: Number | E35: % | F35: Number | G35: % | H35: Number | I35: % | J35: Number | K35: % | L35: Number | M35: % | N35: Number | O35: %
A36: Overall Headcount | B36: 2140 | C36: 1 | D36: 949.66667 | E36: 0.44376947 | F36: 760.33333 | G36: 0.35529595 | H36: 254.66667 | I36: 0.11900312 | J36: 71 | K36: 0.03317757 | L36: 62.666667 | M36: 0.029283489 | N36: 41.666667 | O36: 0.019470405
A37: Direct Staff | B37: 1173.3333 | C37: 0.5482866 | D37: 599.66667 | E37: 0.51107955 | F37: 223.66667 | G37: 0.190625 | H37: 222.33333 | I37: 0.18948864 | J37: 36.666667 | K37: 0.03125 | L37: 58 | M37: 0.049431818 | N37: 33 | O37: 0.028125
A38: Female | B38: 292.66667 | C38: 0.24943182 | D38: 134.33333 | E38: 0.22401334 | F38: 45.666667 | G38: 0.20417288 | H38: 64.666667 | I38: 0.29085457 | J38: 14.333333 | K38: 0.39090909 | L38: 16 | M38: 0.27586207 | N38: 17.666667 | O38: 0.53535354
A39: Male | B39: 880.66667 | C39: 0.75056818 | D39: 465.33333 | E39: 0.77598666 | F39: 178 | G39: 0.79582712 | H39: 157.66667 | I39: 0.70914543 | J39: 22.333333 | K39: 0.60909091 | L39: 42 | M39: 0.72413793 | N39: 15.333333 | O39: 0.46464646
A40: Nationals | B40: 1055.3333 | C40: 0.89943182 | D40: 517.33333 | E40: 0.8627015 | F40: 213 | G40: 0.95230999 | H40: 207.33333 | I40: 0.93253373 | J40: 33 | K40: 0.9 | L40: 52.666667 | M40: 0.90804598 | N40: 32 | O40: 0.96969697
